Workbook

Sheet Hoja1
A1: COD | B1: NOMBRE | C1: OFICINA | D1: Actual | E1: OBSERVACIÓN | F1: TIPO | G1: SUPERVISOR RESPONSABLE | H1: NIVEL DE RIESGO INUNDACION | I1: SENSIBILIDAD A CORTES ELECTRICOS | J1: Ciudad | K1: Provincia | L1: Alimentador | M1: Reserva Glns | N1: Autonomia Max horas | O1: ID | P1: Nivel | Q1: PUNTO DE ATENCIÓN | R1: Riesgo Oleaje | S1: UNICOS | T1: Name | U1: Concatenado | V1: Ubicación | W1: Latitud | X1: Longitud | Y1: Ponderacion Inundaciones | Z1: Inundaciones | AA1: Cortes
A2: 353 | B2: ATM - OF. 12 OCTUBRE | C2: 12 DE OCTUBRE | D2: NO | E2: ABIERTO | F2: OFICINA | G2: Fernando Peralta | H2: Bajo / Seguro | I2: Media (Cortes esporádicos) | J2: =+VLOOKUP(A2,[1]Buscador!$B:$E,4,0) -> Quito | K2: =+VLOOKUP(A2,[1]Buscador!$B:$F,5,0) -> Pichincha | L2: Generador | O2: Bajo / SeguroMedia (Cortes esporádicos) | P2: N3 Moderado | Q2: 12 DE OCTUBRE | R2: NO | S2: 12 DE OCTUBRE | T2: 353-ATM - OF. 12 OCTUBRE | U2: (353-ATM - OF. 12 OCTUBRE) + (A0082-12 DE OCTUBRE) | V2: -0.206033, -78.487366 | W2: -0.206033 | X2: -78.487366 | Y2: 0 | Z2: =+VLOOKUP(I2,Evalua!$G$2:$H$12,2,0) -> 2 | AA2: =+VLOOKUP(I2,Evalua!$G$2:$H$12,2,0) -> 2
A3: A0082 | B3: 12 DE OCTUBRE | C3: 12 DE OCTUBRE | D3: NO | E3: ABIERTO | F3: AGENCIA | G3: Fernando Peralta | H3: Bajo / Seguro | I3: Media (Cortes esporádicos) | J3: =+VLOOKUP(A3,[1]Buscador!$B:$E,4,0) -> Quito | K3: =+VLOOKUP(A3,[1]Buscador!$B:$F,5,0) -> Pichincha | L3: Generador | O3: Bajo / SeguroMedia (Cortes esporádicos) | P3: N3 Moderado | Q3: 12 DE OCTUBRE | R3: NO | S3: 9 DE OCTUBRE | T3: A0082-12 DE OCTUBRE | U3: (61-ATM - OF. 9 DE OCTUBRE) + (A0001-9 DE OCTUBRE) | V3: -0.206033, -78.487366 | W3: -0.206033 | X3: -78.487366 | Y3: 0 | Z3: =+VLOOKUP(H3,Evalua!$G$2:$H$12,2,0) -> 1 | AA3: =+VLOOKUP(I3,Evalua!$G$2:$H$12,2,0) -> 2
A4: 61 | B4: ATM - OF. 9 DE OCTUBRE | C4: 9 DE OCTUBRE | D4: NO | E4: ABIERTO | F4: OFICINA | G4: Gerardo Pulgarín | H4: Bajo / Seguro | I4: Media (Cortes esporádicos) | J4: =+VLOOKUP(A4,[1]Buscador!$B:$E,4,0) -> Guayaquil | K4: =+VLOOKUP(A4,[1]Buscador!$B:$F,5,0) -> Guayas | L4: Generador | O4: Bajo / SeguroMedia (Cortes esporádicos) | P4: N3 Moderado | Q4: 9 DE OCTUBRE | R4: NO | S4: AEROPUERTO ADUANAS | T4: 61-ATM - OF. 9 DE OCTUBRE | U4: (291-ATM - ADUANAS - AEROPUERTO OF.) + (A0049-AEROPUERTO ADUANAS) | V4: -2.187578912005, -79.895072277516 | W4: -2.1875789 | X4: -79.895072 | Y4: 0 | Z4: =+VLOOKUP(H4,Evalua!$G$2:$H$12,2,0) -> 1 | AA4: =+VLOOKUP(I4,Evalua!$G$2:$H$12,2,0) -> 2
A5: A0001 | B5: 9 DE OCTUBRE | C5: 9 DE OCTUBRE | D5: NO | E5: ABIERTO | F5: AGENCIA | G5: Gerardo Pulgarín | H5: Bajo / Seguro | I5: Media (Cortes esporádicos) | J5: =+VLOOKUP(A5,[1]Buscador!$B:$E,4,0) -> Guayaquil | K5: =+VLOOKUP(A5,[1]Buscador!$B:$F,5,0) -> Guayas | L5: Generador | M5: 50 | N5: 17 | O5: Bajo / SeguroMedia (Cortes esporádicos) | P5: N3 Moderado | Q5: 9 DE OCTUBRE | R5: NO | S5: AEROPUERTO J.J. DE OLMEDO | T5: A0001-9 DE OCTUBRE | U5: (145-ATM - AEROPUERTO GYE. 2 OF.) + (A0050-AEROPUERTO J.J. DE OLMEDO) | V5: -2.187578912005, -79.895072277516 | W5: -2.1875789 | X5: -79.895072 | Y5: 0 | Z5: =+VLOOKUP(H5,Evalua!$G$2:$H$12,2,0) -> 1 | AA5: =+VLOOKUP(I5,Evalua!$G$2:$H$12,2,0) -> 2
A6: 291 | B6: ATM - ADUANAS - AEROPUERTO OF. | C6: TERMINAL TERRESTRE | D6: NO | E6: ABIERTO | F6: OFICINA | G6: Gerardo Pulgarín | H6: Bajo / Seguro | I6: Media (Cortes esporádicos) | J6: =+VLOOKUP(A6,[1]Buscador!$B:$E,4,0) -> Guayaquil | K6: =+VLOOKUP(A6,[1]Buscador!$B:$F,5,0) -> Guayas | L6: Generador | O6: Bajo / SeguroMedia (Cortes esporádicos) | P6: N3 Moderado | Q6: AEROPUERTO ADUANAS | R6: NO | S6: ALBORADA NORTE | T6: 291-ATM - ADUANAS - AEROPUERTO OF. | U6: (165-ATM - OF. ALBORADA NORTE 1) + (166-ATM - OF. ALBORADA NORTE 2) + (A0003-ALBORADA NORTE) | V6: -2.15271811535, -79.885611603149 | W6: -2.1527181 | X6: -79.885612 | Y6: 0 | Z6: =+VLOOKUP(H6,Evalua!$G$2:$H$12,2,0) -> 1 | AA6: =+VLOOKUP(I6,Evalua!$G$2:$H$12,2,0) -> 2
A7: A0049 | B7: AEROPUERTO ADUANAS | C7: AEROPUERTO ADUANAS | D7: NO | E7: ABIERTO | F7: VENTANILLA DE EXTENSION | G7: Gerardo Pulgarín | H7: Bajo / Seguro | I7: Media (Cortes esporádicos) | J7: =+VLOOKUP(A7,[1]Buscador!$B:$E,4,0) -> Guayaquil | K7: =+VLOOKUP(A7,[1]Buscador!$B:$F,5,0) -> Guayas | L7: Generador | O7: Bajo / SeguroMedia (Cortes esporádicos) | P7: N3 Moderado | Q7: AEROPUERTO ADUANAS | R7: NO | S7: ATM - OF. ALBORADA AUTOCAJERO | T7: A0049-AEROPUERTO ADUANAS | U7: (4-ATM - OF. ALBORADA AUTOCAJERO) | V7: -2.15271811535, -79.885611603149 | W7: -2.1527181 | X7: -79.885612 | Y7: 0 | Z7: =+VLOOKUP(H7,Evalua!$G$2:$H$12,2,0) -> 1 | AA7: =+VLOOKUP(I7,Evalua!$G$2:$H$12,2,0) -> 2
A8: 145 | B8: ATM - AEROPUERTO GYE. 2 OF. | C8: TERMINAL TERRESTRE | D8: NO | E8: ABIERTO | F8: OFICINA | G8: Gerardo Pulgarín | H8: Bajo / Seguro | I8: Media (Cortes esporádicos) | J8: =+VLOOKUP(A8,[1]Buscador!$B:$E,4,0) -> Guayaquil | K8: =+VLOOKUP(A8,[1]Buscador!$B:$F,5,0) -> Guayas | L8: Generador | O8: Bajo / SeguroMedia (Cortes esporádicos) | P8: N3 Moderado | Q8: AEROPUERTO J.J. DE OLMEDO | R8: NO | S8: ALBORADA ORELLANA | T8: 145-ATM - AEROPUERTO GYE. 2 OF. | U8: (51-ATM - OF. ALBORADA PEATONAL) + (470-ATM - OF. ALBORADA RECICLADOR) + (A0002-ALBORADA) | V8: -2.1479507455355, -79.884499354492 | W8: -2.1479507 | X8: -79.884499 | Y8: 0 | Z8: =+VLOOKUP(H8,Evalua!$G$2:$H$12,2,0) -> 1 | AA8: =+VLOOKUP(I8,Evalua!$G$2:$H$12,2,0) -> 2
A9: A0050 | B9: AEROPUERTO J.J. DE OLMEDO | C9: AEROPUERTO J.J. DE OLMEDO | D9: NO | E9: ABIERTO | F9: VENTANILLA DE EXTENSION | G9: Gerardo Pulgarín | H9: Bajo / Seguro | I9: Media (Cortes esporádicos) | J9: =+VLOOKUP(A9,[1]Buscador!$B:$E,4,0) -> Guayaquil | K9: =+VLOOKUP(A9,[1]Buscador!$B:$F,5,0) -> Guayas | L9: Generador | O9: Bajo / SeguroMedia (Cortes esporádicos) | P9: N3 Moderado | Q9: AEROPUERTO J.J. DE OLMEDO | R9: NO | S9: AMBATO CENTRO | T9: A0050-AEROPUERTO J.J. DE OLMEDO | U9: (48-ATM - OF. AMBATO CENTRO) + (A0074-AMBATO) | V9: -2.1479507455355, -79.884499354492 | W9: -2.1479507 | X9: -79.884499 | Y9: 0 | Z9: =+VLOOKUP(H9,Evalua!$G$2:$H$12,2,0) -> 1 | AA9: =+VLOOKUP(I9,Evalua!$G$2:$H$12,2,0) -> 2
A10: 165 | B10: ATM - OF. ALBORADA NORTE 1 | C10: ALBORADA NORTE | D10: NO | E10: ABIERTO | F10: OFICINA | G10: Gerardo Pulgarín | H10: Medio (Se inunda la calle) | I10: Media (Cortes esporádicos) | J10: =+VLOOKUP(A10,[1]Buscador!$B:$E,4,0) -> Guayaquil | K10: =+VLOOKUP(A10,[1]Buscador!$B:$F,5,0) -> Guayas | L10: Generador | O10: Medio (Se inunda la calle)Media (Cortes esporádicos) | P10: N2 Alto | Q10: ALBORADA NORTE | R10: NO | S10: ARCA CALDERON | T10: 165-ATM - OF. ALBORADA NORTE 1 | U10: (A0092-ARCA CALDERON) | V10: -2.1335977860225, -79.904058839287 | W10: -2.1335978 | X10: -79.904059 | Y10: 0 | Z10: =+VLOOKUP(H10,Evalua!$G$2:$H$12,2,0) -> 3 | AA10: =+VLOOKUP(I10,Evalua!$G$2:$H$12,2,0) -> 2
A11: 166 | B11: ATM - OF. ALBORADA NORTE 2 | C11: ALBORADA NORTE | D11: NO | E11: ABIERTO | F11: OFICINA | G11: Gerardo Pulgarín | H11: Medio (Se inunda la calle) | I11: Media (Cortes esporádicos) | J11: =+VLOOKUP(A11,[1]Buscador!$B:$E,4,0) -> Guayaquil | K11: =+VLOOKUP(A11,[1]Buscador!$B:$F,5,0) -> Guayas | L11: Generador | O11: Medio (Se inunda la calle)Media (Cortes esporádicos) | P11: N2 Alto | Q11: ALBORADA NORTE | R11: NO | S11: ARCA HUAYANAY QUITO | T11: 166-ATM - OF. ALBORADA NORTE 2 | U11: (A0091-ARCA HUAYANAY QUITO) | V11: -2.1335977860225, -79.904058839287 | W11: -2.1335978 | X11: -79.904059 | Y11: 0 | Z11: =+VLOOKUP(H11,Evalua!$G$2:$H$12,2,0) -> 3 | AA11: =+VLOOKUP(I11,Evalua!$G$2:$H$12,2,0) -> 2
A12: A0003 | B12: ALBORADA NORTE | C12: ALBORADA NORTE | D12: NO | E12: ABIERTO | F12: AGENCIA | G12: Gerardo Pulgarín | H12: Medio (Se inunda la calle) | I12: Media (Cortes esporádicos) | J12: =+VLOOKUP(A12,[1]Buscador!$B:$E,4,0) -> Guayaquil | K12: =+VLOOKUP(A12,[1]Buscador!$B:$F,5,0) -> Guayas | L12: Generador | M12: 250 | N12: 10.625 | O12: Medio (Se inunda la calle)Media (Cortes esporádicos) | P12: N2 Alto | Q12: ALBORADA NORTE | R12: NO | S12: ARCA JUAN TANCA MARENGO | T12: A0003-ALBORADA NORTE | U12: (A0035-ARCA JUAN TANCA MARENGO) | V12: -2.1335977860225, -79.904058839287 | W12: -2.1335978 | X12: -79.904059 | Y12: 0 | Z12: =+VLOOKUP(H12,Evalua!$G$2:$H$12,2,0) -> 3 | AA12: =+VLOOKUP(I12,Evalua!$G$2:$H$12,2,0) -> 2
A13: 4 | B13: ATM - OF. ALBORADA AUTOCAJERO | C13: MATRIZ-TEVCOL | D13: NO | E13: ABIERTO | F13: ISLA | G13: Gerardo Pulgarín | H13: Bajo / Seguro | I13: Media (Cortes esporádicos) | J13: =+VLOOKUP(A13,[1]Buscador!$B:$E,4,0) -> Guayaquil | K13: =+VLOOKUP(A13,[1]Buscador!$B:$F,5,0) -> Guayas | L13: Generador | O13: Bajo / SeguroMedia (Cortes esporádicos) | P13: N3 Moderado | Q13: ATM - OF. ALBORADA AUTOCAJERO | R13: NO | S13: ARCA OTAVALO | T13: 4-ATM - OF. ALBORADA AUTOCAJERO | U13: (A0100-ARCA OTAVALO) | V13: -2.1477533987468, -79.899858642948 | W13: -2.1477534 | X13: -79.899859 | Y13: 0 | Z13: =+VLOOKUP(H13,Evalua!$G$2:$H$12,2,0) -> 1 | AA13: =+VLOOKUP(I13,Evalua!$G$2:$H$12,2,0) -> 2
A14: 51 | B14: ATM - OF. ALBORADA PEATONAL | C14: ALBORADA | D14: NO | E14: ABIERTO | F14: OFICINA | G14: Gerardo Pulgarín | H14: Bajo / Seguro | I14: Media (Cortes esporádicos) | J14: =+VLOOKUP(A14,[1]Buscador!$B:$E,4,0) -> Guayaquil | K14: =+VLOOKUP(A14,[1]Buscador!$B:$F,5,0) -> Guayas | L14: Generador | O14: Bajo / SeguroMedia (Cortes esporádicos) | P14: N3 Moderado | Q14: ALBORADA ORELLANA | R14: NO | S14: ARCA PARQUE INDUSTRIAL CUENCA | T14: 51-ATM - OF. ALBORADA PEATONAL | U14: (A0090-ARCA PARQUE INDUSTRIAL CUENCA) | V14: -2.1477533987468, -79.899858642948 | W14: -2.1477534 | X14: -79.899859 | Y14: 0 | Z14: =+VLOOKUP(H14,Evalua!$G$2:$H$12,2,0) -> 1 | AA14: =+VLOOKUP(I14,Evalua!$G$2:$H$12,2,0) -> 2
A15: 470 | B15: ATM - OF. ALBORADA RECICLADOR | C15: ALBORADA | D15: NO | E15: ABIERTO | F15: OFICINA | G15: Gerardo Pulgarín | H15: Bajo / Seguro | I15: Media (Cortes esporádicos) | J15: =+VLOOKUP(A15,[1]Buscador!$B:$E,4,0) -> Guayaquil | K15: =+VLOOKUP(A15,[1]Buscador!$B:$F,5,0) -> Guayas | L15: Generador | O15: Bajo / SeguroMedia (Cortes esporádicos) | P15: N3 Moderado | Q15: ALBORADA ORELLANA | R15: NO | S15: ARCA PORTOVIEJO | T15: 470-ATM - OF. ALBORADA RECICLADOR | U15: (402-ATM - ARCA PORTOVIEJO) + (A0037-ARCA PORTOVIEJO) | V15: -2.1477533987468, -79.899858642948 | W15: -2.1477534 | X15: -79.899859 | Y15: 0 | Z15: =+VLOOKUP(H15,Evalua!$G$2:$H$12,2,0) -> 1 | AA15: =+VLOOKUP(I15,Evalua!$G$2:$H$12,2,0) -> 2
A16: A0002 | B16: ALBORADA | C16: ALBORADA | D16: NO | E16: ABIERTO | F16: AGENCIA | G16: Gerardo Pulgarín | H16: Bajo / Seguro | I16: Media (Cortes esporádicos) | J16: =+VLOOKUP(A16,[1]Buscador!$B:$E,4,0) -> Guayaquil | K16: =+VLOOKUP(A16,[1]Buscador!$B:$F,5,0) -> Guayas | L16: Generador | M16: 70 | N16: 8.2638889 | O16: Bajo / SeguroMedia (Cortes esporádicos) | P16: N3 Moderado | Q16: ALBORADA ORELLANA | R16: NO | S16: ARCA QUEVEDO | T16: A0002-ALBORADA | U16: (422-ATM - ARCA QUEVEDO) + (A0038-ARCA QUEVEDO) | V16: -2.1477533987468, -79.899858642948 | W16: -2.1477534 | X16: -79.899859 | Y16: 0 | Z16: =+VLOOKUP(H16,Evalua!$G$2:$H$12,2,0) -> 1 | AA16: =+VLOOKUP(I16,Evalua!$G$2:$H$12,2,0) -> 2
A17: 48 | B17: ATM - OF. AMBATO CENTRO | C17: AMBATO | D17: NO | E17: ABIERTO | F17: OFICINA | G17: Fernando Peralta | H17: Crítico (Se inunda punto de atención) | I17: Media (Cortes esporádicos) | J17: =+VLOOKUP(A17,[1]Buscador!$B:$E,4,0) -> Ambato | K17: =+VLOOKUP(A17,[1]Buscador!$B:$F,5,0) -> Tungurahua | L17: Generador | O17: Crítico (Se inunda punto de atención)Media (Cortes esporádicos) | P17: N1 Crítico | Q17: AMBATO CENTRO | R17: NO | S17: ARCA SANTO DOMINGO | T17: 48-ATM - OF. AMBATO CENTRO | U17: (A0039-ARCA SANTO DOMINGO) | V17: -1.2413417400182, -78.628491327921 | W17: -1.2413417 | X17: -78.628491 | Y17: 0 | Z17: =+VLOOKUP(H17,Evalua!$G$2:$H$12,2,0) -> 4 | AA17: =+VLOOKUP(I17,Evalua!$G$2:$H$12,2,0) -> 2
A18: A0074 | B18: AMBATO | C18: AMBATO | D18: NO | E18: ABIERTO | F18: AGENCIA | G18: Fernando Peralta | H18: Crítico (Se inunda punto de atención) | I18: Media (Cortes esporádicos) | J18: =+VLOOKUP(A18,[1]Buscador!$B:$E,4,0) -> Ambato | K18: =+VLOOKUP(A18,[1]Buscador!$B:$F,5,0) -> Tungurahua | L18: Generador | M18: 15 | N18: 5.5434783 | O18: Crítico (Se inunda punto de atención)Media (Cortes esporádicos) | P18: N1 Crítico | Q18: AMBATO CENTRO | R18: NO | S18: ARCA VIA A DAULE | T18: A0074-AMBATO | U18: (A0040-ARCA VIA A DAULE) | V18: -1.2413417400182, -78.628491327921 | W18: -1.2413417 | X18: -78.628491 | Y18: 0 | Z18: =+VLOOKUP(H18,Evalua!$G$2:$H$12,2,0) -> 4 | AA18: =+VLOOKUP(I18,Evalua!$G$2:$H$12,2,0) -> 2
A19: A0092 | B19: ARCA CALDERON | C19: ARCA CALDERON | D19: NO | E19: ABIERTO | F19: VENTANILLA DE EMPRESA | G19: Fernando Peralta | H19: Bajo / Seguro | I19: Media (Cortes esporádicos) | J19: =+VLOOKUP(A19,[1]Buscador!$B:$E,4,0) -> Carapungo | K19: =+VLOOKUP(A19,[1]Buscador!$B:$F,5,0) -> Pichincha | L19: Generador | M19: 5 | N19: 8.5 | O19: Bajo / SeguroMedia (Cortes esporádicos) | P19: N3 Moderado | Q19: ARCA CALDERON | R19: NO | S19: ARCA VIA PASAJE MACHALA | T19: A0092-ARCA CALDERON | U19: (A0036-ARCA VIA PASAJE MACHALA) | V19: -0.10572923708953, -78.443399190862 | W19: -0.10572924 | X19: -78.443399 | Y19: 0 | Z19: =+VLOOKUP(H19,Evalua!$G$2:$H$12,2,0) -> 1 | AA19: =+VLOOKUP(I19,Evalua!$G$2:$H$12,2,0) -> 2
A20: A0091 | B20: ARCA HUAYANAY QUITO | C20: ARCA HUAYANAY QUITO | D20: NO | E20: ABIERTO | F20: VENTANILLA DE EMPRESA | G20: Fernando Peralta | H20: Bajo / Seguro | I20: Media (Cortes esporádicos) | J20: =+VLOOKUP(A20,[1]Buscador!$B:$E,4,0) -> Quito | K20: =+VLOOKUP(A20,[1]Buscador!$B:$F,5,0) -> Pichincha | L20: Generador | O20: Bajo / SeguroMedia (Cortes esporádicos) | P20: N3 Moderado | Q20: ARCA HUAYANAY QUITO | R20: NO | S20: ATM - ACERO COMERCIAL QUITO | T20: A0091-ARCA HUAYANAY QUITO | U20: (150-ATM - ACERO COMERCIAL QUITO) | V20: -0.30416769242810987, -78.54273899138401 | W20: -0.30416769 | X20: -78.542739 | Y20: 0 | Z20: =+VLOOKUP(H20,Evalua!$G$2:$H$12,2,0) -> 1 | AA20: =+VLOOKUP(I20,Evalua!$G$2:$H$12,2,0) -> 2
A21: A0035 | B21: ARCA JUAN TANCA MARENGO | C21: ARCA JUAN TANCA MARENGO | D21: NO | E21: ABIERTO | F21: VENTANILLA DE EMPRESA | G21: Gerardo Pulgarín | H21: Bajo / Seguro | I21: Media (Cortes esporádicos) | J21: =+VLOOKUP(A21,[1]Buscador!$B:$E,4,0) -> Guayaquil | K21: =+VLOOKUP(A21,[1]Buscador!$B:$F,5,0) -> Guayas | L21: Generador | O21: Bajo / SeguroMedia (Cortes esporádicos) | P21: N3 Moderado | Q21: ARCA JUAN TANCA MARENGO | R21: NO | S21: ATM - ALHAMBRA SHOPPING | T21: A0035-ARCA JUAN TANCA MARENGO | U21: (443-ATM - ALHAMBRA SHOPPING) | V21: -2.1436198698285, -79.914839904091 | W21: -2.1436199 | X21: -79.91484 | Y21: 0 | Z21: =+VLOOKUP(H21,Evalua!$G$2:$H$12,2,0) -> 1 | AA21: =+VLOOKUP(I21,Evalua!$G$2:$H$12,2,0) -> 2
A22: A0100 | B22: ARCA OTAVALO | C22: ARCA OTAVALO | D22: NO | E22: ABIERTO | F22: VENTANILLA DE EMPRESA | G22: Fernando Peralta | H22: Bajo / Seguro | I22: Media (Cortes esporádicos) | J22: =+VLOOKUP(A22,[1]Buscador!$B:$E,4,0) -> San Juan deI lumán | K22: =+VLOOKUP(A22,[1]Buscador!$B:$F,5,0) -> Imbabura | L22: NO | O22: Bajo / SeguroMedia (Cortes esporádicos) | P22: N3 Moderado | Q22: ARCA OTAVALO | R22: NO | S22: ATM - ALMAX CENTER | T22: A0100-ARCA OTAVALO | U22: (548-ATM - ALMAX CENTER) | V22: 0.276139, -78.239348 | W22: 0.276139 | X22: -78.239348 | Y22: 0 | Z22: =+VLOOKUP(H22,Evalua!$G$2:$H$12,2,0) -> 1 | AA22: =+VLOOKUP(I22,Evalua!$G$2:$H$12,2,0) -> 2
A23: A0090 | B23: ARCA PARQUE INDUSTRIAL CUENCA | C23: ARCA PARQUE INDUSTRIAL CUENCA | D23: NO | E23: ABIERTO | F23: VENTANILLA DE EMPRESA | G23: Miguel Rojas | H23: Bajo / Seguro | I23: Alta (Corte inmediato) | J23: =+VLOOKUP(A23,[1]Buscador!$B:$E,4,0) -> Cuenca | K23: =+VLOOKUP(A23,[1]Buscador!$B:$F,5,0) -> Azuay | L23: Generador | O23: Bajo / SeguroAlta (Corte inmediato) | P23: N2 Alto | Q23: ARCA PARQUE INDUSTRIAL CUENCA | R23: NO | S23: ATM - ARCA EL INCA | T23: A0090-ARCA PARQUE INDUSTRIAL CUENCA | U23: (399-ATM - ARCA EL INCA) | V23: -2.881478, -78.975129 | W23: -2.881478 | X23: -78.975129 | Y23: 0 | Z23: =+VLOOKUP(H23,Evalua!$G$2:$H$12,2,0) -> 1 | AA23: =+VLOOKUP(I23,Evalua!$G$2:$H$12,2,0) -> 3
A24: 402 | B24: ATM - ARCA PORTOVIEJO | C24: PORTOVIEJO | D24: NO | E24: ABIERTO | F24: OFICINA | G24: José Mendoza | H24: Crítico (Se inunda punto de atención) | I24: Media (Cortes esporádicos) | J24: =+VLOOKUP(A24,[1]Buscador!$B:$E,4,0) -> Portoviejo | K24: =+VLOOKUP(A24,[1]Buscador!$B:$F,5,0) -> Manabí | L24: Generador | O24: Crítico (Se inunda punto de atención)Media (Cortes esporádicos) | P24: N1 Crítico | Q24: ARCA PORTOVIEJO | R24: NO | S24: ATM - ARCA JUAN TANCA MARENGO | T24: 402-ATM - ARCA PORTOVIEJO | U24: (398-ATM - ARCA JUAN TANCA MARENGO) | V24: -1.073357, -80.444453 | W24: -1.073357 | X24: -80.444453 | Y24: 0 | Z24: =+VLOOKUP(H24,Evalua!$G$2:$H$12,2,0) -> 4 | AA24: =+VLOOKUP(I24,Evalua!$G$2:$H$12,2,0) -> 2
A25: A0037 | B25: ARCA PORTOVIEJO | C25: ARCA PORTOVIEJO | D25: SI | E25: ABIERTO | F25: VENTANILLA DE EMPRESA | G25: José Mendoza | H25: Crítico (Se inunda punto de atención) | I25: Media (Cortes esporádicos) | J25: =+VLOOKUP(A25,[1]Buscador!$B:$E,4,0) -> Portoviejo | K25: =+VLOOKUP(A25,[1]Buscador!$B:$F,5,0) -> Manabí | L25: Generador | O25: Crítico (Se inunda punto de atención)Media (Cortes esporádicos) | P25: N1 Crítico | Q25: ARCA PORTOVIEJO | R25: NO | S25: ATM - ARCA QUITO CALDERON | T25: A0037-ARCA PORTOVIEJO | U25: (396-ATM - ARCA QUITO CALDERON) | V25: -1.073357, -80.444453 | W25: -1.073357 | X25: -80.444453 | Y25: 0 | Z25: =+VLOOKUP(H25,Evalua!$G$2:$H$12,2,0) -> 4 | AA25: =+VLOOKUP(I25,Evalua!$G$2:$H$12,2,0) -> 2
A26: 422 | B26: ATM - ARCA QUEVEDO | C26: QUEVEDO | D26: NO | E26: ABIERTO | F26: OFICINA | G26: Fabián Burgos | H26: Bajo / Seguro | I26: Alta (Corte inmediato) | J26: =+VLOOKUP(A26,[1]Buscador!$B:$E,4,0) -> Quevedo | K26: =+VLOOKUP(A26,[1]Buscador!$B:$F,5,0) -> Los Ríos | L26: Generador | O26: Bajo / SeguroAlta (Corte inmediato) | P26: N2 Alto | Q26: ARCA QUEVEDO | R26: NO | S26: ATM - ARCA SANTO DOMINGO | T26: 422-ATM - ARCA QUEVEDO | U26: (397-ATM - ARCA SANTO DOMINGO) | V26: -0.97913, -79.440004 | W26: -0.97913 | X26: -79.440004 | Y26: 0 | Z26: =+VLOOKUP(H26,Evalua!$G$2:$H$12,2,0) -> 1 | AA26: =+VLOOKUP(I26,Evalua!$G$2:$H$12,2,0) -> 3
A27: A0038 | B27: ARCA QUEVEDO | C27: ARCA QUEVEDO | D27: NO | E27: ABIERTO | F27: VENTANILLA DE EMPRESA | G27: Fabián Burgos | H27: Bajo / Seguro | I27: Alta (Corte inmediato) | J27: =+VLOOKUP(A27,[1]Buscador!$B:$E,4,0) -> Quevedo | K27: =+VLOOKUP(A27,[1]Buscador!$B:$F,5,0) -> Los Ríos | L27: Generador | O27: Bajo / SeguroAlta (Corte inmediato) | P27: N2 Alto | Q27: ARCA QUEVEDO | R27: NO | S27: ATM - ARCA VIA A DAULE | T27: A0038-ARCA QUEVEDO | U27: (395-ATM - ARCA VIA A DAULE) | V27: -0.97913, -79.440004 | W27: -0.97913 | X27: -79.440004 | Y27: 0 | Z27: =+VLOOKUP(H27,Evalua!$G$2:$H$12,2,0) -> 1 | AA27: =+VLOOKUP(I27,Evalua!$G$2:$H$12,2,0) -> 3
A28: A0039 | B28: ARCA SANTO DOMINGO | C28: ARCA SANTO DOMINGO | D28: NO | E28: ABIERTO | F28: VENTANILLA DE EMPRESA | G28: Carlos Morán | H28: Bajo / Seguro | I28: Alta (Corte inmediato) | J28: =+VLOOKUP(A28,[1]Buscador!$B:$E,4,0) -> Santo Domingo de los Tsachilas | K28: =+VLOOKUP(A28,[1]Buscador!$B:$F,5,0) -> Santo Domingo de los Tsáchilas | L28: Generador | O28: Bajo / SeguroAlta (Corte inmediato) | P28: N2 Alto | Q28: ARCA SANTO DOMINGO | R28: NO | S28: ATM - ATARAZANA HOSP. R. GILBERT | T28: A0039-ARCA SANTO DOMINGO | U28: (108-ATM - ATARAZANA HOSP. R. GILBERT) | V28: -0.25710976049203, -79.204541208058 | W28: -0.25710976 | X28: -79.204541 | Y28: 0 | Z28: =+VLOOKUP(H28,Evalua!$G$2:$H$12,2,0) -> 1 | AA28: =+VLOOKUP(I28,Evalua!$G$2:$H$12,2,0) -> 3
A29: A0040 | B29: ARCA VIA A DAULE | C29: ARCA VIA A DAULE | D29: NO | E29: ABIERTO | F29: VENTANILLA DE EMPRESA | G29: Gerardo Pulgarín | H29: Bajo / Seguro | I29: Media (Cortes esporádicos) | J29: =+VLOOKUP(A29,[1]Buscador!$B:$E,4,0) -> Guayaquil | K29: =+VLOOKUP(A29,[1]Buscador!$B:$F,5,0) -> Guayas | L29: Generador | O29: Bajo / SeguroMedia (Cortes esporádicos) | P29: N3 Moderado | Q29: ARCA VIA A DAULE | R29: NO | S29: ATM - AV. LA ECUATORIANA | T29: A0040-ARCA VIA A DAULE | U29: (437-ATM - AV. LA ECUATORIANA) | V29: -2.110533, -79.937646 | W29: -2.110533 | X29: -79.937646 | Y29: 0 | Z29: =+VLOOKUP(H29,Evalua!$G$2:$H$12,2,0) -> 1 | AA29: =+VLOOKUP(I29,Evalua!$G$2:$H$12,2,0) -> 2
A30: A0036 | B30: ARCA VIA PASAJE MACHALA | C30: ARCA VIA PASAJE MACHALA | D30: NO | E30: ABIERTO | F30: VENTANILLA DE EMPRESA | G30: Washington Reyes | H30: Medio (Se inunda la calle) | I30: Alta (Corte inmediato) | J30: =+VLOOKUP(A30,[1]Buscador!$B:$E,4,0) -> Machala | K30: =+VLOOKUP(A30,[1]Buscador!$B:$F,5,0) -> El Oro | L30: Generador | O30: Medio (Se inunda la calle)Alta (Corte inmediato) | P30: N1 Crítico | Q30: ARCA VIA PASAJE MACHALA | R30: NO | S30: ATM - AVICOLA FERNANDEZ , AV. ISI | T30: A0036-ARCA VIA PASAJE MACHALA | U30: (249-ATM - AVICOLA FERNANDEZ , AV. ISI) | V30: -3.274044, -79.935957 | W30: -3.274044 | X30: -79.935957 | Y30: 0 | Z30: =+VLOOKUP(H30,Evalua!$G$2:$H$12,2,0) -> 3 | AA30: =+VLOOKUP(I30,Evalua!$G$2:$H$12,2,0) -> 3
A31: 150 | B31: ATM - ACERO COMERCIAL QUITO | C31: MATRIZ-TEVCOL | D31: NO | E31: ABIERTO | F31: ISLA | G31: Fernando Peralta | H31: Medio (Se inunda la calle) | I31: Media (Cortes esporádicos) | J31: =+VLOOKUP(A31,[1]Buscador!$B:$E,4,0) -> Quito | K31: =+VLOOKUP(A31,[1]Buscador!$B:$F,5,0) -> Pichincha | L31: NO | O31: Medio (Se inunda la calle)Media (Cortes esporádicos) | P31: N2 Alto | Q31: ATM - ACERO COMERCIAL QUITO | R31: NO | S31: ATM - AVÍCOLA FERNANDEZ BABAHOYO | T31: 150-ATM - ACERO COMERCIAL QUITO | U31: (496-ATM - AVÍCOLA FERNANDEZ BABAHOYO) | V31: -0.158622, -78.488167 | W31: -0.158622 | X31: -78.488167 | Y31: 0 | Z31: =+VLOOKUP(H31,Evalua!$G$2:$H$12,2,0) -> 3 | AA31: =+VLOOKUP(I31,Evalua!$G$2:$H$12,2,0) -> 2
... A69: 497 | B69: ATM - DURAN BUSINESS CENTER | C69: MATRIZ-TEVCOL | D69: NO | E69: ABIERTO | F69: ISLA | G69: Gerardo Pulgarín | H69: Bajo / Seguro | I69: Media (Cortes esporádicos) | J69: =+VLOOKUP(A69,[1]Buscador!$B:$E,4,0) -> Durán | K69: =+VLOOKUP(A69,[1]Buscador!$B:$F,5,0) -> Guayas | L69: Generador | O69: Bajo / SeguroMedia (Cortes esporádicos) | P69: N3 Moderado | Q69: ATM - DURAN BUSINESS CENTER | R69: NO | S69: ATM - GARZOCENTRO SHOPPING CENTER | T69: 497-ATM - DURAN BUSINESS CENTER | U69: (458-ATM - GARZOCENTRO SHOPPING CENTER) | V69: -2.188029909433, -79.827955918632 | W69: -2.1880299 | X69: -79.827956 | Y69: 0 | Z69: =+VLOOKUP(H69,Evalua!$G$2:$H$12,2,0) -> 1 | AA69: =+VLOOKUP(I69,Evalua!$G$2:$H$12,2,0) -> 2
A70: 546 | B70: ATM - DURAN EL RECREO 3 ETAPA | C70: MATRIZ-TEVCOL | D70: NO | E70: ABIERTO | F70: ISLA | G70: Gerardo Pulgarín | H70: Medio (Se inunda la calle) | I70: Alta (Corte inmediato) | J70: =+VLOOKUP(A70,[1]Buscador!$B:$E,4,0) -> Durán | K70: =+VLOOKUP(A70,[1]Buscador!$B:$F,5,0) -> Guayas | L70: Baterias | M70: 0 | N70: 3 | O70: Medio (Se inunda la calle)Alta (Corte inmediato) | P70: N1 Crítico | Q70: ATM - DURAN EL RECREO 3 ETAPA | R70: NO | S70: ATM - GAS PETROCOMERCIAL SUR | T70: 546-ATM - DURAN EL RECREO 3 ETAPA | U70: (233-ATM - GAS PETROCOMERCIAL SUR) | V70: -2.17431566775777, -79.8037642790764 | W70: -2.1743157 | X70: -79.803764 | Y70: 0 | Z70: =+VLOOKUP(H70,Evalua!$G$2:$H$12,2,0) -> 3 | AA70: =+VLOOKUP(I70,Evalua!$G$2:$H$12,2,0) -> 3
A71: 511 | B71: ATM - ECOTEC | C71: MATRIZ-TEVCOL | D71: NO | E71: ABIERTO | F71: ISLA | G71: Gerardo Pulgarín | H71: Bajo / Seguro | I71: Media (Cortes esporádicos) | J71: =+VLOOKUP(A71,[1]Buscador!$B:$E,4,0) -> Samborondón | K71: =+VLOOKUP(A71,[1]Buscador!$B:$F,5,0) -> Guayas | L71: Generador | O71: Bajo / SeguroMedia (Cortes esporádicos) | P71: N3 Moderado | Q71: ATM - ECOTEC | R71: NO | S71: ATM - GAS. HERMANO MIGUEL AV. 25 | T71: 511-ATM - ECOTEC | U71: (247-ATM - GAS. HERMANO MIGUEL AV. 25) | V71: -2.0383602154564, -79.857352980223 | W71: -2.0383602 | X71: -79.857353 | Y71: 0 | Z71: =+VLOOKUP(H71,Evalua!$G$2:$H$12,2,0) -> 1 | AA71: =+VLOOKUP(I71,Evalua!$G$2:$H$12,2,0) -> 2
A72: 334 | B72: ATM - FAR. CRUZ AZUL SAUCES 9 | C72: MATRIZ-TEVCOL | D72: NO | E72: ABIERTO | F72: ISLA | G72: Gerardo Pulgarín | H72: Medio (Se inunda la calle) | I72: Media (Cortes esporádicos) | J72: =+VLOOKUP(A72,[1]Buscador!$B:$E,4,0) -> Guayaquil | K72: =+VLOOKUP(A72,[1]Buscador!$B:$F,5,0) -> Guayas | L72: NO | O72: Medio (Se inunda la calle)Media (Cortes esporádicos) | P72: N2 Alto | Q72: ATM - FAR. CRUZ AZUL SAUCES 9 | R72: NO | S72: ATM - GAS. PDV TERMINAL PASCUALES | T72: 334-ATM - FAR. CRUZ AZUL SAUCES 9 | U72: (429-ATM - GAS. PDV TERMINAL PASCUALES) | V72: -2.128026, -79.892673 | W72: -2.128026 | X72: -79.892673 | Y72: 0 | Z72: =+VLOOKUP(H72,Evalua!$G$2:$H$12,2,0) -> 3 | AA72: =+VLOOKUP(I72,Evalua!$G$2:$H$12,2,0) -> 2
A73: 131 | B73: ATM - FARM. CRUZ AZUL MARTHA DE R | C73: MATRIZ-TEVCOL | D73: NO | E73: ABIERTO | F73: ISLA | G73: Gerardo Pulgarín | H73: Bajo / Seguro | I73: Media (Cortes esporádicos) | J73: =+VLOOKUP(A73,[1]Buscador!$B:$E,4,0) -> Guayaquil | K73: =+VLOOKUP(A73,[1]Buscador!$B:$F,5,0) -> Guayas | L73: NO | O73: Bajo / SeguroMedia (Cortes esporádicos) | P73: N3 Moderado | Q73: ATM - FARM. CRUZ AZUL MARTHA DE R | R73: NO | S73: ATM - GAS. PETROLEOS Y SERVICIOS | T73: 131-ATM - FARM. CRUZ AZUL MARTHA DE R | U73: (159-ATM - GAS. PETROLEOS Y SERVICIOS) | V73: -2.1450553375999, -79.922635587483 | W73: -2.1450553 | X73: -79.922636 | Y73: 0 | Z73: =+VLOOKUP(H73,Evalua!$G$2:$H$12,2,0) -> 1 | AA73: =+VLOOKUP(I73,Evalua!$G$2:$H$12,2,0) -> 2
A74: 451 | B74: ATM - FARM. CRUZ AZUL POMASQUI | C74: MATRIZ-TEVCOL | D74: NO | E74: ABIERTO | F74: ISLA | G74: Fernando Peralta | H74: Medio (Se inunda la calle) | I74: Alta (Corte inmediato) | J74: =+VLOOKUP(A74,[1]Buscador!$B:$E,4,0) -> Distrito Metropolitano de Quito | K74: =+VLOOKUP(A74,[1]Buscador!$B:$F,5,0) -> Pichincha | L74: NO | O74: Medio (Se inunda la calle)Alta (Corte inmediato) | P74: N1 Crítico | Q74: ATM - FARM. CRUZ AZUL POMASQUI | R74: NO | S74: ATM - GAS. PETROMAR | T74: 451-ATM - FARM. CRUZ AZUL POMASQUI | U74: (474-ATM - GAS. PETROMAR) | V74: -0.054045, -78.455478 | W74: -0.054045 | X74: -78.455478 | Y74: 0 | Z74: =+VLOOKUP(H74,Evalua!$G$2:$H$12,2,0) -> 3 | AA74: =+VLOOKUP(I74,Evalua!$G$2:$H$12,2,0) -> 3
A75: 117 | B75: ATM - FARM. DROMAYOR | C75: MATRIZ-TEVCOL | D75: NO | E75: ABIERTO | F75: ISLA | G75: Gerardo Pulgarín | H75: Bajo / Seguro | I75: Media (Cortes esporádicos) | J75: =+VLOOKUP(A75,[1]Buscador!$B:$E,4,0) -> Guayaquil | K75: =+VLOOKUP(A75,[1]Buscador!$B:$F,5,0) -> Guayas | L75: NO | O75: Bajo / SeguroMedia (Cortes esporádicos) | P75: N3 Moderado | Q75: ATM - FARM. DROMAYOR | R75: NO | S75: ATM - GAS. TERPEL GUAYACANES | T75: 117-ATM - FARM. DROMAYOR | U75: (352-ATM - GAS. TERPEL GUAYACANES) | V75: -2.186439, -79.88382 | W75: -2.186439 | X75: -79.88382 | Y75: 0 | Z75: =+VLOOKUP(H75,Evalua!$G$2:$H$12,2,0) -> 1 | AA75: =+VLOOKUP(I75,Evalua!$G$2:$H$12,2,0) -> 2
A76: 125 | B76: ATM - FARM. PHARMACYS BATAN BAJO | C76: MATRIZ-TEVCOL | D76: NO | E76: ABIERTO | F76: ISLA | G76: Fernando Peralta | H76: Medio (Se inunda la calle) | I76: Alta (Corte inmediato) | J76: =+VLOOKUP(A76,[1]Buscador!$B:$E,4,0) -> Quito | K76: =+VLOOKUP(A76,[1]Buscador!$B:$F,5,0) -> Pichincha | L76: NO | O76: Medio (Se inunda la calle)Alta (Corte inmediato) | P76: N1 Crítico | Q76: ATM - FARM. PHARMACYS BATAN BAJO | R76: NO | S76: ATM - GAS. TERPEL VIA COSTA | T76: 125-ATM - FARM. PHARMACYS BATAN BAJO | U76: (17-ATM - GAS. TERPEL VIA COSTA) | V76: -0.18534561055841, -78.478990546681 | W76: -0.18534561 | X76: -78.478991 | Y76: 0 | Z76: =+VLOOKUP(H76,Evalua!$G$2:$H$12,2,0) -> 3 | AA76: =+VLOOKUP(I76,Evalua!$G$2:$H$12,2,0) -> 3
A77: 151 | B77: ATM - FARM. VICTORIA 29 Y ORIENTE | C77: MATRIZ-TEVCOL | D77: NO | E77: ABIERTO | F77: ISLA | G77: Gerardo Pulgarín | H77: Medio (Se inunda la calle) | I77: Alta (Corte inmediato) | J77: =+VLOOKUP(A77,[1]Buscador!$B:$E,4,0) -> Guayaquil | K77: =+VLOOKUP(A77,[1]Buscador!$B:$F,5,0) -> Guayas | L77: NO | O77: Medio (Se inunda la calle)Alta (Corte inmediato) | P77: N1 Crítico | Q77: ATM - FARM. VICTORIA 29 Y ORIENTE | R77: NO | S77: ATM - GISIS | T77: 151-ATM - FARM. VICTORIA 29 Y ORIENTE | U77: (464-ATM - GISIS) | V77: -2.2111070203254, -79.930980380145 | W77: -2.211107 | X77: -79.93098 | Y77: 0 | Z77: =+VLOOKUP(H77,Evalua!$G$2:$H$12,2,0) -> 3 | AA77: =+VLOOKUP(I77,Evalua!$G$2:$H$12,2,0) -> 3
...

Sheet Evalua
A1: ID | B1: Inundación | C1: Energía | D1: Nivel
A2: Crítico (Se inunda punto de atención)Alta (Corte inmediato) | B2: Crítico (Se inunda punto de atención) | C2: Alta (Corte inmediato) | D2: N1 Crítico | G2: {=+_xlfn.UNIQUE(Hoja1!H:H)} -> NIVEL DE RIESGO INUNDACION
A3: Crítico (Se inunda punto de atención)Media (Cortes esporádicos) | B3: Crítico (Se inunda punto de atención) | C3: Media (Cortes esporádicos) | D3: N1 Crítico | G3: Bajo / Seguro | H3: 1
A4: Crítico (Se inunda punto de atención)Baja (Línea prioritaria) | B4: Crítico (Se inunda punto de atención) | C4: Baja (Línea prioritaria) | D4: N2 Alto | G4: Medio (Se inunda la calle) | H4: 3
A5: Medio (Se inunda la calle)Alta (Corte inmediato) | B5: Medio (Se inunda la calle) | C5: Alta (Corte inmediato) | D5: N1 Crítico | G5: Crítico (Se inunda punto de atención) | H5: 4
A6: Medio (Se inunda la calle)Media (Cortes esporádicos) | B6: Medio (Se inunda la calle) | C6: Media (Cortes esporádicos) | D6: N2 Alto | G6: Medio (Filtracion superficial) | H6: 2
A7: Medio (Se inunda la calle)Baja (Línea prioritaria) | B7: Medio (Se inunda la calle) | C7: Baja (Línea prioritaria) | D7: N3 Moderado | G7: 0
A8: Bajo / SeguroAlta (Corte inmediato) | B8: Bajo / Seguro | C8: Alta (Corte inmediato) | D8: N2 Alto
A9: Bajo / SeguroMedia (Cortes esporádicos) | B9: Bajo / Seguro | C9: Media (Cortes esporádicos) | D9: N3 Moderado | G9: {=+_xlfn.UNIQUE(Hoja1!I:I)} -> SENSIBILIDAD A CORTES ELECTRICOS
A10: Bajo / SeguroBaja (Línea prioritaria) | B10: Bajo / Seguro | C10: Baja (Línea prioritaria) | D10: N4 Bajo | G10: Media (Cortes esporádicos) | H10: 2
A11: Medio (Filtracion superficial)Alta (Corte inmediato) | B11: Medio (Filtracion superficial) | C11: Alta (Corte inmediato) | D11: N2 Alto | G11: Alta (Corte inmediato) | H11: 3
A12: Medio (Filtracion superficial)Media (Cortes esporádicos) | B12: Medio (Filtracion superficial) | C12: Media (Cortes esporádicos) | D12: N3 Moderado | G12: Baja (Línea prioritaria) | H12: 1
A13: Medio (Filtracion superficial)Baja (Línea prioritaria) | B13: Medio (Filtracion superficial) | C13: Baja (Línea prioritaria) | D13: N4 Bajo | G13: 0

Sheet Hoja2
A1: ¿Nivel de Riesgo Inundación? | C1: ¿Sensibilidad a Cortes Eléctricos?
A2: Crítico (Se inunda punto de atención) | B2: Requiere obras físicas / mover equipos. | C2: Alta (Corte inmediato) | D2: Alta (Corte inmediato) | E2: Alta (Corte inmediato) | F2: Se va la luz apenas llueve o parpadea la red.
A3: Medio (Se inunda la calle) | B3: Afecta acceso de clientes y técnicos. | C3: Media (Cortes esporádicos) | D3: Media (Cortes esporádicos) | E3: Media (Cortes esporádicos) | F3: La red de la zona es relativamente estable.
A4: Bajo / Seguro | B4: Zona segura contra lluvias. | C4: Baja (Línea prioritaria) | D4: Baja (Línea prioritaria) | E4: Baja (Línea prioritaria) | F4: Zona de hospitales, centros cívicos o industrias.
A5: Medio (Filtracion superficial)

Sheet Hoja3
A1: ID | B1: Nombre | C1: Punto de atencion | D1: Ciudad | E1: Inundacion | F1: Electricidad | G1: Nivel | P1: Provincia | Q1: Puntos | R1: N1 | S1: N2 | T1: N3 | U1: N4
A2: 48 | B2: AMBATO CENTRO | C2: (48-ATM - OF. AMBATO CENTRO) + (A0074-AMBATO) | D2: AMBATO | E2: Crítico (Se inunda punto de atención) | F2: Media (Cortes esporádicos) | G2: N1 Crítico | P2: Guayas | Q2: 185 | R2: 7 | S2: 13 | T2: 165 | U2: 0
A3: 63 | B3: MILAGRO | C3: (63-ATM - OF. MILAGRO) + (360-ATM - OF. MILAGRO 2) + (A0022-MILAGRO) | D3: MILAGRO | E3: Crítico (Se inunda punto de atención) | F3: Media (Cortes esporádicos) | G3: N1 Crítico | P3: Pichincha | Q3: 45 | R3: 2 | S3: 4 | T3: 39 | U3: 0
A4: 77 | B4: BABAHOYO | C4: (77-ATM - OF. BABAHOYO) + (A0004-BABAHOYO) | D4: BABAHOYO | E4: Medio (Se inunda la calle) | F4: Alta (Corte inmediato) | G4: N1 Crítico | P4: Manabí | Q4: 14 | R4: 5 | S4: 7 | T4: 1 | U4: 1
A5: 125 | B5: ATM - FARM. PHARMACYS BATAN BAJO | C5: (125-ATM - FARM. PHARMACYS BATAN BAJO) | D5: QUITO | E5: Medio (Se inunda la calle) | F5: Alta (Corte inmediato) | G5: N1 Crítico | P5: Santa Elena | Q5: 13 | R5: 0 | S5: 0 | T5: 13 | U5: 0
A6: 151 | B6: ATM - FARM. VICTORIA 29 Y ORIENTE | C6: (151-ATM - FARM. VICTORIA 29 Y ORIENTE) | D6: GUAYAQUIL | E6: Medio (Se inunda la calle) | F6: Alta (Corte inmediato) | G6: N1 Crítico | P6: Los Ríos | Q6: 8 | R6: 3 | S6: 5 | T6: 0 | U6: 0
A7: 216 | B7: ATM - MAPASINGUE OESTE | C7: (216-ATM - MAPASINGUE OESTE) | D7: GUAYAQUIL | E7: Medio (Se inunda la calle) | F7: Alta (Corte inmediato) | G7: N1 Crítico | P7: Azuay | Q7: 7 | R7: 0 | S7: 2 | T7: 5 | U7: 0
A8: 221 | B8: ATM - SAUCES VI | C8: (221-ATM - SAUCES VI) | D8: GUAYAQUIL | E8: Crítico (Se inunda punto de atención) | F8: Media (Cortes esporádicos) | G8: N1 Crítico | P8: Tungurahua | Q8: 6 | R8: 1 | S8: 2 | T8: 3 | U8: 0
A9: 301 | B9: ATM - MANTA FLAVIO REYES Y CALLE | C9: (301-ATM - MANTA FLAVIO REYES Y CALLE) | D9: MANTA | E9: Crítico (Se inunda punto de atención) | F9: Alta (Corte inmediato) | G9: N1 Crítico | P9: Sto Domingo | Q9: 5 | R9: 0 | S9: 2 | T9: 0 | U9: 3
A10: 332 | B10: ATM - TIA DURAN III | C10: (332-ATM - TIA DURAN III) | D10: DURAN | E10: Medio (Se inunda la calle) | F10: Alta (Corte inmediato) | G10: N1 Crítico | P10: El Oro | Q10: 3 | R10: 1 | S10: 0 | T10: 0 | U10: 2
A11: 336 | B11: ATM - TER. TERREST. PORTOVIEJO | C11: (336-ATM - TER. TERREST. PORTOVIEJO) | D11: PORTOVIEJO | E11: Medio (Se inunda la calle) | F11: Alta (Corte inmediato) | G11: N1 Crítico | P11: Cañar | Q11: 3 | R11: 0 | S11: 0 | T11: 3 | U11: 0
A12: 392 | B12: ATM - PASEO SHOPPING BABAHOYO | C12: (392-ATM - PASEO SHOPPING BABAHOYO) | D12: BABAHOYO | E12: Crítico (Se inunda punto de atención) | F12: Media (Cortes esporádicos) | G12: N1 Crítico | P12: Loja | Q12: 1 | R12: 0 | S12: 0 | T12: 1 | U12: 0
... A15: 435 | B15: ATM - CENTRO PORTOVIEJO | C15: (435-ATM - CENTRO PORTOVIEJO) | D15: PORTOVIEJO | E15: Crítico (Se inunda punto de atención) | F15: Alta (Corte inmediato) | G15: N1 Crítico | P15: Imbabura | Q15: 1 | R15: 0 | S15: 0 | T15: 1 | U15: 0
A16: 451 | B16: ATM - FARM. CRUZ AZUL POMASQUI | C16: (451-ATM - FARM. CRUZ AZUL POMASQUI) | D16: QUITO | E16: Medio (Se inunda la calle) | F16: Alta (Corte inmediato) | G16: N1 Crítico
A17: 496 | B17: ATM - AVÍCOLA FERNANDEZ BABAHOYO | C17: (496-ATM - AVÍCOLA FERNANDEZ BABAHOYO) | D17: BABAHOYO | E17: Medio (Se inunda la calle) | F17: Alta (Corte inmediato) | G17: N1 Crítico
A18: 543 | B18: ATM - TUTI DURANEL RECREO 1° ETAPA | C18: (543-ATM - TUTI DURANEL RECREO 1° ETAPA) | D18: DURAN | E18: Medio (Se inunda la calle) | F18: Alta (Corte inmediato) | G18: N1 Crítico
A19: 546 | B19: ATM - DURAN EL RECREO 3 ETAPA | C19: (546-ATM - DURAN EL RECREO 3 ETAPA) | D19: DURAN | E19: Medio (Se inunda la calle) | F19: Alta (Corte inmediato) | G19: N1 Crítico
A20: A0036 | B20: ARCA VIA PASAJE MACHALA | C20: (A0036-ARCA VIA PASAJE MACHALA) | D20: MACHALA | E20: Medio (Se inunda la calle) | F20: Alta (Corte inmediato) | G20: N1 Crítico
A21: 2 | B21: URDESA | C21: (2-ATM - OF. URDESA 1) + (52-ATM - OF. URDESA 2) + (A0033-URDESA) | D21: GUAYAQUIL | E21: Medio (Se inunda la calle) | F21: Media (Cortes esporádicos) | G21: N2 Alto
A22: 6 | B22: QUEVEDO | C22: (6-ATM - OF. QUEVEDO) + (373-ATM - OF. QUEVEDO 2) + (A0028-QUEVEDO) | D22: QUEVEDO | E22: Bajo / Seguro | F22: Alta (Corte inmediato) | G22: N2 Alto
A23: 21 | B23: VIA DAULE | C23: (21-ATM - GAS. MOBIL VIA DAULE OF.) + (A0069-VIA DAULE) | D23: GUAYAQUIL | E23: Medio (Se inunda la calle) | F23: Media (Cortes esporádicos) | G23: N2 Alto
A24: 28 | B24: MANTA | C24: (28-ATM - OF. MANTA) + (A0019-MANTA) | D24: MANTA | E24: Medio (Se inunda la calle) | F24: Media (Cortes esporádicos) | G24: N2 Alto
A25: 34 | B25: PORTOVIEJO | C25: (34-ATM - OF. PORTOVIEJO) + (A0027-PORTOVIEJO) | D25: PORTOVIEJO | E25: Medio (Se inunda la calle) | F25: Media (Cortes esporádicos) | G25: N2 Alto
A26: 40 | B26: EL EMPALME | C26: (40-ATM - OF. EL EMPALME) + (356-ATM - OF EL EMPALME 2) + (A0009-EL EMPALME) | D26: EL EMPALME | E26: Bajo / Seguro | F26: Alta (Corte inmediato) | G26: N2 Alto
A27: 42 | B27: BUENA FE | C27: (42-ATM - OF. BUENA FE) + (A0005-BUENA FE) | D27: BUENA FE | E27: Bajo / Seguro | F27: Alta (Corte inmediato) | G27: N2 Alto
... A295: 447 | B295: MACHALA | C295: (447-ATM - AG. MACHALA) + (A0016-MACHALA) | D295: MACHALA | E295: Bajo / Seguro | F295: Baja (Línea prioritaria) | G295: N4 Bajo
