Workbook

Sheet Hoja1
A1: COD | B1: NOMBRE | C1: Comentario | D1: Inundaciones | E1: Altitud | F1: Riesgo | G1: OFICINA | H1: Actual | I1: OBSERVACIÓN | J1: TIPO | K1: SUPERVISOR RESPONSABLE | L1: NIVEL DE RIESGO INUNDACION | M1: SENSIBILIDAD A CORTES ELECTRICOS | N1: Ciudad | O1: Provincia | P1: Alimentador | Q1: Reserva Glns | R1: Autonomia Max horas | S1: ID | T1: Nivel | U1: PUNTO DE ATENCIÓN | V1: Riesgo Oleaje | W1: UNICOS | X1: Name | Y1: Concatenado | Z1: Ubicación | AA1: Latitud | AB1: Longitud | AC1: Ponderacion Inundaciones | AD1: Inundaciones | AE1: Cortes
A2: 10 | B2: ATM - OF. CENTRO HISTORICO DE CUE | G2: CUENCA CENTRO | H2: NO | I2: ABIERTO | J2: OFICINA | K2: Miguel Rojas | L2: Bajo / Seguro | M2: Media (Cortes esporádicos) | N2: =+VLOOKUP(A2,[1]Buscador!$B:$E,4,0) -> Cuenca | O2: =+VLOOKUP(A2,[1]Buscador!$B:$F,5,0) -> Azuay | P2: Generador | S2: Bajo / SeguroMedia (Cortes esporádicos) | T2: N3 Moderado | U2: CUENCA CENTRO | V2: NO | W2: MATRIZ | X2: 10-ATM - OF. CENTRO HISTORICO DE CUE | Y2: (508-ATM - OF. MATRIZ LOBBY 2) + (519-ATM - OF. MATRIZ LOBBY RE) + (A0020-MATRIZ) | Z2: -2.8980204687422, -79.002912303961 | AA2: -2.8980205 | AB2: -79.002912 | AC2: 0 | AD2: =+VLOOKUP(L2,Evalua!$G$2:$H$12,2,0) -> 1 | AE2: =+VLOOKUP(M2,Evalua!$G$2:$H$12,2,0) -> 2
A3: 101 | B3: ATM - POSORJA FABRICA SALICA | D3: Alto-Critico | E3: 0-10m | G3: PLAYAS | H3: NO | I3: ABIERTO | J3: OFICINA | K3: Gerardo Pulgarín | L3: Bajo / Seguro | M3: Media (Cortes esporádicos) | N3: =+VLOOKUP(A3,[1]Buscador!$B:$E,4,0) -> Posorja | O3: =+VLOOKUP(A3,[1]Buscador!$B:$F,5,0) -> Guayas | P3: Generador | S3: Bajo / SeguroMedia (Cortes esporádicos) | T3: N3 Moderado | U3: SALICA | V3: NO | X3: 101-ATM - POSORJA FABRICA SALICA | Z3: -2.6981972431688, -80.248583733184 | AA3: -2.6981972 | AB3: -80.248584 | AC3: 0 | AD3: =+VLOOKUP(L3,Evalua!$G$2:$H$12,2,0) -> 1 | AE3: =+VLOOKUP(M3,Evalua!$G$2:$H$12,2,0) -> 2
A4: 102 | B4: ATM - C.C. PASEO MILAGRO PATIO DE | D4: Medio-Alto | E4: 10-15m | G4: MATRIZ-TEVCOL | H4: NO | I4: ABIERTO | J4: ISLA | K4: Gerardo Pulgarín | L4: Bajo / Seguro | M4: Media (Cortes esporádicos) | N4: =+VLOOKUP(A4,[1]Buscador!$B:$E,4,0) -> Milagro | O4: =+VLOOKUP(A4,[1]Buscador!$B:$F,5,0) -> Guayas | P4: Generador | S4: Bajo / SeguroMedia (Cortes esporádicos) | T4: N3 Moderado | U4: ATM - C.C. PASEO MILAGRO PATIO DE | V4: NO | W4: ATM - CD TUTI VIA DAULE | X4: 102-ATM - C.C. PASEO MILAGRO PATIO DE | Y4: (513-ATM - CD TUTI VIA DAULE) | Z4: -2.1364964620815, -79.594431549598 | AA4: -2.1364965 | AB4: -79.594432 | AC4: 0 | AD4: =+VLOOKUP(L4,Evalua!$G$2:$H$12,2,0) -> 1 | AE4: =+VLOOKUP(M4,Evalua!$G$2:$H$12,2,0) -> 2
A5: 104 | B5: ATM - UNIV. SAN FRANCISCO DE QUIT | G5: MATRIZ-TEVCOL | H5: NO | I5: ABIERTO | J5: ISLA | K5: Fernando Peralta | L5: Bajo / Seguro | M5: Media (Cortes esporádicos) | N5: =+VLOOKUP(A5,[1]Buscador!$B:$E,4,0) -> Cumbaya | O5: =+VLOOKUP(A5,[1]Buscador!$B:$F,5,0) -> Pichincha | P5: Generador | S5: Bajo / SeguroMedia (Cortes esporádicos) | T5: N3 Moderado | U5: ATM - UNIV. SAN FRANCISCO DE QUIT | V5: NO | W5: CENTRO EMPRESARIAL COLON | X5: 104-ATM - UNIV. SAN FRANCISCO DE QUIT | Y5: (351-ATM - CENTRO EMPRESARIAL COLON) + (A0052-CENTRO EMPRESARIAL COLON) | Z5: -0.196763, -78.435913 | AA5: -0.196763 | AB5: -78.435913 | AC5: 0 | AD5: =+VLOOKUP(L5,Evalua!$G$2:$H$12,2,0) -> 1 | AE5: =+VLOOKUP(M5,Evalua!$G$2:$H$12,2,0) -> 2
A6: 105 | B6: ATM - OF. EL CARMEN | D6: Medio | E6: +200m | G6: EL CARMEN | H6: NO | I6: ABIERTO | J6: OFICINA | K6: Carlos Morán | L6: Bajo / Seguro | M6: Baja (Línea prioritaria) | N6: =+VLOOKUP(A6,[1]Buscador!$B:$E,4,0) -> El Carmen | O6: =+VLOOKUP(A6,[1]Buscador!$B:$F,5,0) -> Manabí | P6: Generador | S6: Bajo / SeguroBaja (Línea prioritaria) | T6: N4 Bajo | U6: EL CARMEN | V6: NO | W6: PASEO SHOPPING AMBATO | X6: 105-ATM - OF. EL CARMEN | Y6: (134-ATM - PASEO SHOPPING AMBATO) + (A0099-PASEO SHOPPING AMBATO) | Z6: -0.27234110224082, -79.462855468174 | AA6: -0.2723411 | AB6: -79.462855 | AC6: 0 | AD6: =+VLOOKUP(L6,Evalua!$G$2:$H$12,2,0) -> 1 | AE6: =+VLOOKUP(M6,Evalua!$G$2:$H$12,2,0) -> 3
A7: 106 | B7: ATM - HYPERMARKET VIA DAULE | D7: Medio | E7: 5-10m | G7: MATRIZ-TEVCOL | H7: NO | I7: ABIERTO | J7: ISLA | K7: Gerardo Pulgarín | L7: Medio (Se inunda la calle) | M7: Baja (Línea prioritaria) | N7: =+VLOOKUP(A7,[1]Buscador!$B:$E,4,0) -> Guayaquil | O7: =+VLOOKUP(A7,[1]Buscador!$B:$F,5,0) -> Guayas | P7: Generador | S7: Medio (Se inunda la calle)Baja (Línea prioritaria) | T7: N3 Moderado | U7: ATM - HYPERMARKET VIA DAULE | V7: NO | W7: ATM - MERCADO ARTESANAL 2 | X7: 106-ATM - HYPERMARKET VIA DAULE | Y7: (533-ATM - MERCADO ARTESANAL 2) | Z7: -2.1593596393913, -79.92793582209 | AA7: -2.1593596 | AB7: -79.927936 | AC7: 0 | AD7: =+VLOOKUP(L7,Evalua!$G$2:$H$12,2,0) -> 3 | AE7: =+VLOOKUP(M7,Evalua!$G$2:$H$12,2,0) -> 3
A8: 107 | B8: ATM - C.C. POLICENTRO 2 OF. | D8: Medio-Alto | E8: 5-10m | G8: POLICENTRO | H8: NO | I8: ABIERTO | J8: OFICINA | K8: Gerardo Pulgarín | L8: Bajo / Seguro | M8: Media (Cortes esporádicos) | N8: =+VLOOKUP(A8,[1]Buscador!$B:$E,4,0) -> Guayaquil | O8: =+VLOOKUP(A8,[1]Buscador!$B:$F,5,0) -> Guayas | P8: Generador | S8: Bajo / SeguroMedia (Cortes esporádicos) | T8: N3 Moderado | U8: POLICENTRO | V8: NO | X8: 107-ATM - C.C. POLICENTRO 2 OF. | Z8: -2.171177, -79.900567 | AA8: -2.171177 | AB8: -79.900567 | AC8: 0 | AD8: =+VLOOKUP(L8,Evalua!$G$2:$H$12,2,0) -> 1 | AE8: =+VLOOKUP(M8,Evalua!$G$2:$H$12,2,0) -> 2
A9: 108 | B9: ATM - ATARAZANA HOSP. R. GILBERT | E9: 10-15m | G9: MATRIZ-TEVCOL | H9: NO | I9: ABIERTO | J9: ISLA | K9: Gerardo Pulgarín | L9: Bajo / Seguro | M9: Media (Cortes esporádicos) | N9: =+VLOOKUP(A9,[1]Buscador!$B:$E,4,0) -> Guayaquil | O9: =+VLOOKUP(A9,[1]Buscador!$B:$F,5,0) -> Guayas | P9: Generador | S9: Bajo / SeguroMedia (Cortes esporádicos) | T9: N3 Moderado | U9: ATM - ATARAZANA HOSP. R. GILBERT | V9: NO | W9: ATM - C.C. PLAZA NOVA KM. 2.5 VIA | X9: 108-ATM - ATARAZANA HOSP. R. GILBERT | Y9: (294-ATM - C.C. PLAZA NOVA KM. 2.5 VIA) | Z9: -2.1770491363457, -79.883544288361 | AA9: -2.1770491 | AB9: -79.883544 | AC9: 0 | AD9: =+VLOOKUP(L9,Evalua!$G$2:$H$12,2,0) -> 1 | AE9: =+VLOOKUP(M9,Evalua!$G$2:$H$12,2,0) -> 2
A10: 11 | B10: ATM - OF. SUC. QUITO HALL 1 | G10: QUITO SUCURSAL MAYOR | H10: NO | I10: ABIERTO | J10: OFICINA | K10: Fernando Peralta | L10: Bajo / Seguro | M10: Media (Cortes esporádicos) | N10: =+VLOOKUP(A10,[1]Buscador!$B:$E,4,0) -> Quito | O10: =+VLOOKUP(A10,[1]Buscador!$B:$F,5,0) -> Pichincha | P10: Generador | S10: Bajo / SeguroMedia (Cortes esporádicos) | T10: N3 Moderado | U10: QUITO SUCURSAL MAYOR | V10: NO | X10: 11-ATM - OF. SUC. QUITO HALL 1 | Z10: -0.17596927121457, -78.482782898148 | AA10: -0.17596927 | AB10: -78.482783 | AC10: 0 | AD10: =+VLOOKUP(L10,Evalua!$G$2:$H$12,2,0) -> 1 | AE10: =+VLOOKUP(M10,Evalua!$G$2:$H$12,2,0) -> 2
A11: 110 | B11: ATM - C.C. CALIFORNIA 2 OF. | D11: Alto | E11: 10-20m | G11: PARQUE INDUSTRIAL CALIFORNIA | H11: NO | I11: ABIERTO | J11: OFICINA | K11: Gerardo Pulgarín | L11: Medio (Se inunda la calle) | M11: Baja (Línea prioritaria) | N11: =+VLOOKUP(A11,[1]Buscador!$B:$E,4,0) -> Guayaquil | O11: =+VLOOKUP(A11,[1]Buscador!$B:$F,5,0) -> Guayas | P11: Generador | S11: Medio (Se inunda la calle)Baja (Línea prioritaria) | T11: N3 Moderado | U11: PARQUE INDUSTRIAL CALIFORNIA | V11: NO | X11: 110-ATM - C.C. CALIFORNIA 2 OF. | Z11: -2.098622, -79.936398 | AA11: -2.098622 | AB11: -79.936398 | AC11: 0 | AD11: =+VLOOKUP(L11,Evalua!$G$2:$H$12,2,0) -> 3 | AE11: =+VLOOKUP(M11,Evalua!$G$2:$H$12,2,0) -> 3
A12: 114 | B12: ATM - C.C. SAN MARINO 2 OF. | D12: Medio-Alto | E12: 5-10m | G12: SAN MARINO | H12: NO | I12: ABIERTO | J12: OFICINA | K12: Gerardo Pulgarín | L12: Bajo / Seguro | M12: Media (Cortes esporádicos) | N12: =+VLOOKUP(A12,[1]Buscador!$B:$E,4,0) -> Guayaquil | O12: =+VLOOKUP(A12,[1]Buscador!$B:$F,5,0) -> Guayas | P12: Generador | S12: Bajo / SeguroMedia (Cortes esporádicos) | T12: N3 Moderado | U12: SAN MARINO | V12: NO | X12: 114-ATM - C.C. SAN MARINO 2 OF. | Z12: -2.1694677273972, -79.89852522833 | AA12: -2.1694677 | AB12: -79.898525 | AC12: 0 | AD12: =+VLOOKUP(L12,Evalua!$G$2:$H$12,2,0) -> 1 | AE12: =+VLOOKUP(M12,Evalua!$G$2:$H$12,2,0) -> 2
A13: 116 | B13: ATM - TIA AV. OLMEDO | D13: Medio-Alto | E13: 0-5m | G13: MATRIZ-TEVCOL | H13: NO | I13: ABIERTO | J13: ISLA | K13: Gerardo Pulgarín | L13: Bajo / Seguro | M13: Media (Cortes esporádicos) | N13: =+VLOOKUP(A13,[1]Buscador!$B:$E,4,0) -> Guayaquil | O13: =+VLOOKUP(A13,[1]Buscador!$B:$F,5,0) -> Guayas | P13: Generador | S13: Bajo / SeguroMedia (Cortes esporádicos) | T13: N3 Moderado | U13: ATM - TIA AV. OLMEDO | V13: NO | W13: ATM - TIA LLANO GRANDE | X13: 116-ATM - TIA AV. OLMEDO | Y13: (509-ATM - TIA LLANO GRANDE) | Z13: -2.198379622975, -79.884574652712 | AA13: -2.1983796 | AB13: -79.884575 | AC13: 0 | AD13: =+VLOOKUP(L13,Evalua!$G$2:$H$12,2,0) -> 1 | AE13: =+VLOOKUP(M13,Evalua!$G$2:$H$12,2,0) -> 2
A14: 117 | B14: ATM - FARM. DROMAYOR | E14: 5-10m | G14: MATRIZ-TEVCOL | H14: NO | I14: ABIERTO | J14: ISLA | K14: Gerardo Pulgarín | L14: Bajo / Seguro | M14: Media (Cortes esporádicos) | N14: =+VLOOKUP(A14,[1]Buscador!$B:$E,4,0) -> Guayaquil | O14: =+VLOOKUP(A14,[1]Buscador!$B:$F,5,0) -> Guayas | P14: NO | S14: Bajo / SeguroMedia (Cortes esporádicos) | T14: N3 Moderado | U14: ATM - FARM. DROMAYOR | V14: NO | W14: ATM - GAS. TERPEL GUAYACANES | X14: 117-ATM - FARM. DROMAYOR | Y14: (352-ATM - GAS. TERPEL GUAYACANES) | Z14: -2.186439, -79.88382 | AA14: -2.186439 | AB14: -79.88382 | AC14: 0 | AD14: =+VLOOKUP(L14,Evalua!$G$2:$H$12,2,0) -> 1 | AE14: =+VLOOKUP(M14,Evalua!$G$2:$H$12,2,0) -> 2
A15: 118 | B15: ATM - HYPERMARKET ALBAN BORJA | E15: 10-15m | G15: MATRIZ-TEVCOL | H15: NO | I15: ABIERTO | J15: ISLA | K15: Gerardo Pulgarín | L15: Bajo / Seguro | M15: Media (Cortes esporádicos) | N15: =+VLOOKUP(A15,[1]Buscador!$B:$E,4,0) -> Guayaquil | O15: =+VLOOKUP(A15,[1]Buscador!$B:$F,5,0) -> Guayas | P15: Generador | S15: Bajo / SeguroMedia (Cortes esporádicos) | T15: N3 Moderado | U15: ATM - HYPERMARKET ALBAN BORJA | V15: NO | W15: ATM - MANTA FLAVIO REYES Y CALLE | X15: 118-ATM - HYPERMARKET ALBAN BORJA | Y15: (301-ATM - MANTA FLAVIO REYES Y CALLE) | Z15: -2.1707506252272, -79.916886046627 | AA15: -2.1707506 | AB15: -79.916886 | AC15: 0 | AD15: =+VLOOKUP(L15,Evalua!$G$2:$H$12,2,0) -> 1 | AE15: =+VLOOKUP(M15,Evalua!$G$2:$H$12,2,0) -> 2
A16: 12 | B16: ATM - OF. SUC. QUITO HALL 2 | G16: QUITO SUCURSAL MAYOR | H16: NO | I16: ABIERTO | J16: OFICINA | K16: Fernando Peralta | L16: Bajo / Seguro | M16: Media (Cortes esporádicos) | N16: =+VLOOKUP(A16,[1]Buscador!$B:$E,4,0) -> Quito | O16: =+VLOOKUP(A16,[1]Buscador!$B:$F,5,0) -> Pichincha | P16: Generador | S16: Bajo / SeguroMedia (Cortes esporádicos) | T16: N3 Moderado | U16: QUITO SUCURSAL MAYOR | V16: NO | X16: 12-ATM - OF. SUC. QUITO HALL 2 | Z16: -0.17596927121457, -78.482782898148 | AA16: -0.17596927 | AB16: -78.482783 | AC16: 0 | AD16: =+VLOOKUP(L16,Evalua!$G$2:$H$12,2,0) -> 1 | AE16: =+VLOOKUP(M16,Evalua!$G$2:$H$12,2,0) -> 2
A17: 120 | B17: ATM - PORTETE Y LA 17 | C17: Se inunda la calle del sector | D17: Alto | E17: 5-10m | G17: MATRIZ-TEVCOL | H17: NO | I17: ABIERTO | J17: ISLA | K17: Gerardo Pulgarín | L17: Bajo / Seguro | M17: Media (Cortes esporádicos) | N17: =+VLOOKUP(A17,[1]Buscador!$B:$E,4,0) -> Guayaquil | O17: =+VLOOKUP(A17,[1]Buscador!$B:$F,5,0) -> Guayas | P17: NO | S17: Bajo / SeguroMedia (Cortes esporádicos) | T17: N3 Moderado | U17: ATM - PORTETE Y LA 17 | V17: NO | W17: ATM - PRIMAX ENTRE RIOS | X17: 120-ATM - PORTETE Y LA 17 | Y17: (198-ATM - PRIMAX ENTRE RIOS) | Z17: -2.2016875712695, -79.916651315123 | AA17: -2.2016876 | AB17: -79.916651 | AC17: 0 | AD17: =+VLOOKUP(L17,Evalua!$G$2:$H$12,2,0) -> 1 | AE17: =+VLOOKUP(M17,Evalua!$G$2:$H$12,2,0) -> 2
A18: 123 | B18: ATM - TIA SANTA ELENA | E18: 40-50m | G18: MATRIZ-TEVCOL | H18: NO | I18: ABIERTO | J18: ISLA | K18: Gerardo Pulgarín | L18: Bajo / Seguro | M18: Media (Cortes esporádicos) | N18: =+VLOOKUP(A18,[1]Buscador!$B:$E,4,0) -> Santa Elena | O18: =+VLOOKUP(A18,[1]Buscador!$B:$F,5,0) -> Santa Elena | P18: NO | S18: Bajo / SeguroMedia (Cortes esporádicos) | T18: N3 Moderado | U18: ATM - TIA SANTA ELENA | V18: NO | W18: ATM - UEES | X18: 123-ATM - TIA SANTA ELENA | Y18: (445-ATM - UEES) | Z18: -2.2264001623105, -80.858451644245 | AA18: -2.2264002 | AB18: -80.858452 | AC18: 0 | AD18: =+VLOOKUP(L18,Evalua!$G$2:$H$12,2,0) -> 1 | AE18: =+VLOOKUP(M18,Evalua!$G$2:$H$12,2,0) -> 2
A19: 125 | B19: ATM - FARM. PHARMACYS BATAN BAJO | G19: MATRIZ-TEVCOL | H19: NO | I19: ABIERTO | J19: ISLA | K19: Fernando Peralta | L19: Medio (Se inunda la calle) | M19: Alta (Corte inmediato) | N19: =+VLOOKUP(A19,[1]Buscador!$B:$E,4,0) -> Quito | O19: =+VLOOKUP(A19,[1]Buscador!$B:$F,5,0) -> Pichincha | P19: NO | S19: Medio (Se inunda la calle)Alta (Corte inmediato) | T19: N1 Crítico | U19: ATM - FARM. PHARMACYS BATAN BAJO | V19: NO | W19: ATM - GAS. TERPEL VIA COSTA | X19: 125-ATM - FARM. PHARMACYS BATAN BAJO | Y19: (17-ATM - GAS. TERPEL VIA COSTA) | Z19: -0.18534561055841, -78.478990546681 | AA19: -0.18534561 | AB19: -78.478991 | AC19: 0 | AD19: =+VLOOKUP(L19,Evalua!$G$2:$H$12,2,0) -> 3 | AE19: =+VLOOKUP(M19,Evalua!$G$2:$H$12,2,0) -> 1
A20: 13 | B20: ATM - C.C.RIOCENTRO LOS CEIBOS OF | D20: Bajo | E20: 20-25m | G20: RIOCENTRO LOS CEIBOS | H20: NO | I20: ABIERTO | J20: OFICINA | K20: Gerardo Pulgarín | L20: Bajo / Seguro | M20: Media (Cortes esporádicos) | N20: =+VLOOKUP(A20,[1]Buscador!$B:$E,4,0) -> Guayaquil | O20: =+VLOOKUP(A20,[1]Buscador!$B:$F,5,0) -> Guayas | P20: Generador | S20: Bajo / SeguroMedia (Cortes esporádicos) | T20: N3 Moderado | U20: RIOCENTRO CEIBOS | V20: NO | X20: 13-ATM - C.C.RIOCENTRO LOS CEIBOS OF | Z20: -2.1775527356936, -79.942488674591 | AA20: -2.1775527 | AB20: -79.942489 | AC20: 0 | AD20: =+VLOOKUP(L20,Evalua!$G$2:$H$12,2,0) -> 1 | AE20: =+VLOOKUP(M20,Evalua!$G$2:$H$12,2,0) -> 2
A21: 131 | B21: ATM - FARM. CRUZ AZUL MARTHA DE R | E21: 20-25m | G21: MATRIZ-TEVCOL | H21: NO | I21: ABIERTO | J21: ISLA | K21: Gerardo Pulgarín | L21: Bajo / Seguro | M21: Media (Cortes esporádicos) | N21: =+VLOOKUP(A21,[1]Buscador!$B:$E,4,0) -> Guayaquil | O21: =+VLOOKUP(A21,[1]Buscador!$B:$F,5,0) -> Guayas | P21: NO | S21: Bajo / SeguroMedia (Cortes esporádicos) | T21: N3 Moderado | U21: ATM - FARM. CRUZ AZUL MARTHA DE R | V21: NO | W21: ATM - GAS. PETROLEOS Y SERVICIOS | X21: 131-ATM - FARM. CRUZ AZUL MARTHA DE R | Y21: (159-ATM - GAS. PETROLEOS Y SERVICIOS) | Z21: -2.1450553375999, -79.922635587483 | AA21: -2.1450553 | AB21: -79.922636 | AC21: 0 | AD21: =+VLOOKUP(L21,Evalua!$G$2:$H$12,2,0) -> 1 | AE21: =+VLOOKUP(M21,Evalua!$G$2:$H$12,2,0) -> 2
A22: 134 | B22: ATM - PASEO SHOPPING AMBATO | D22: Bajo | E22: 2570m | G22: PASEO SHOPPING AMBATO | H22: NO | I22: ABIERTO | J22: OFICINA | K22: Fernando Peralta | L22: Bajo / Seguro | M22: Media (Cortes esporádicos) | N22: =+VLOOKUP(A22,[1]Buscador!$B:$E,4,0) -> Ambato | O22: =+VLOOKUP(A22,[1]Buscador!$B:$F,5,0) -> Tungurahua | P22: Generador | S22: Bajo / SeguroMedia (Cortes esporádicos) | T22: N3 Moderado | U22: PASEO SHOPPING AMBATO | V22: NO | X22: 134-ATM - PASEO SHOPPING AMBATO | Z22: -1.2639733631127, -78.64012797686 | AA22: -1.2639734 | AB22: -78.640128 | AC22: 0 | AD22: =+VLOOKUP(L22,Evalua!$G$2:$H$12,2,0) -> 1 | AE22: =+VLOOKUP(M22,Evalua!$G$2:$H$12,2,0) -> 2
A23: 140 | B23: ATM - C.C. MALL DEL SUR 2 OF. | D23: Bajo-Medio | E23: 0-5m | G23: MALL DEL SUR | H23: NO | I23: ABIERTO | J23: OFICINA | K23: Gerardo Pulgarín | L23: Bajo / Seguro | M23: Media (Cortes esporádicos) | N23: =+VLOOKUP(A23,[1]Buscador!$B:$E,4,0) -> Guayaquil | O23: =+VLOOKUP(A23,[1]Buscador!$B:$F,5,0) -> Guayas | P23: Generador | S23: Bajo / SeguroMedia (Cortes esporádicos) | T23: N3 Moderado | U23: MALL DEL SUR | V23: NO | X23: 140-ATM - C.C. MALL DEL SUR 2 OF. | Z23: -2.229148, -79.898457 | AA23: -2.229148 | AB23: -79.898457 | AC23: 0 | AD23: =+VLOOKUP(L23,Evalua!$G$2:$H$12,2,0) -> 1 | AE23: =+VLOOKUP(M23,Evalua!$G$2:$H$12,2,0) -> 2
A24: 141 | B24: ATM - TIA ALBORADA | E24: 5-10m | G24: MATRIZ-TEVCOL | H24: NO | I24: ABIERTO | J24: ISLA | K24: Gerardo Pulgarín | L24: Bajo / Seguro | M24: Media (Cortes esporádicos) | N24: =+VLOOKUP(A24,[1]Buscador!$B:$E,4,0) -> Guayaquil | O24: =+VLOOKUP(A24,[1]Buscador!$B:$F,5,0) -> Guayas | P24: Generador | S24: Bajo / SeguroMedia (Cortes esporádicos) | T24: N3 Moderado | U24: ATM - TIA ALBORADA | V24: NO | W24: ATM - TIA LA MANA | X24: 141-ATM - TIA ALBORADA | Y24: (411-ATM - TIA LA MANA) | Z24: -2.13962, -79.89843 | AA24: -2.13962 | AB24: -79.89843 | AC24: 0 | AD24: =+VLOOKUP(L24,Evalua!$G$2:$H$12,2,0) -> 1 | AE24: =+VLOOKUP(M24,Evalua!$G$2:$H$12,2,0) -> 2
A25: 142 | B25: ATM - C.C. SAN LUIS OF. | G25: QUITO SAN LUIS | H25: NO | I25: ABIERTO | J25: OFICINA | K25: Fernando Peralta | L25: Bajo / Seguro | M25: Media (Cortes esporádicos) | N25: =+VLOOKUP(A25,[1]Buscador!$B:$E,4,0) -> Sangolquí | O25: =+VLOOKUP(A25,[1]Buscador!$B:$F,5,0) -> Pichincha | P25: Generador | S25: Bajo / SeguroMedia (Cortes esporádicos) | T25: N3 Moderado | U25: QUITO SAN LUIS | V25: NO | X25: 142-ATM - C.C. SAN LUIS OF. | Z25: -0.30797568986608, -78.449547381615 | AA25: -0.30797569 | AB25: -78.449547 | AC25: 0 | AD25: =+VLOOKUP(L25,Evalua!$G$2:$H$12,2,0) -> 1 | AE25: =+VLOOKUP(M25,Evalua!$G$2:$H$12,2,0) -> 2
A26: 143 | B26: ATM - TIA MAPASINGUE | E26: 5-10m | G26: MATRIZ-TEVCOL | H26: NO | I26: ABIERTO | J26: ISLA | K26: Gerardo Pulgarín | L26: Bajo / Seguro | M26: Media (Cortes esporádicos) | N26: =+VLOOKUP(A26,[1]Buscador!$B:$E,4,0) -> Guayaquil | O26: =+VLOOKUP(A26,[1]Buscador!$B:$F,5,0) -> Guayas | P26: Generador | S26: Bajo / SeguroMedia (Cortes esporádicos) | T26: N3 Moderado | U26: ATM - TIA MAPASINGUE | V26: NO | W26: ATM - TIA TOACAZO | X26: 143-ATM - TIA MAPASINGUE | Y26: (253-ATM - TIA TOACAZO) | Z26: -2.157744, -79.919684 | AA26: -2.157744 | AB26: -79.919684 | AC26: 0 | AD26: =+VLOOKUP(L26,Evalua!$G$2:$H$12,2,0) -> 1 | AE26: =+VLOOKUP(M26,Evalua!$G$2:$H$12,2,0) -> 2
A27: 145 | B27: ATM - AEROPUERTO GYE. 2 OF. | D27: Bajo | E27: 5-10m | G27: TERMINAL TERRESTRE | H27: NO | I27: ABIERTO | J27: OFICINA | K27: Gerardo Pulgarín | L27: Bajo / Seguro | M27: Media (Cortes esporádicos) | N27: =+VLOOKUP(A27,[1]Buscador!$B:$E,4,0) -> Guayaquil | O27: =+VLOOKUP(A27,[1]Buscador!$B:$F,5,0) -> Guayas | P27: Generador | S27: Bajo / SeguroMedia (Cortes esporádicos) | T27: N3 Moderado | U27: AEROPUERTO J.J. DE OLMEDO | V27: NO | W27: ALBORADA ORELLANA | X27: 145-ATM - AEROPUERTO GYE. 2 OF. | Y27: (51-ATM - OF. ALBORADA PEATONAL) + (470-ATM - OF. ALBORADA RECICLADOR) + (A0002-ALBORADA) | Z27: -2.1479507455355, -79.884499354492 | AA27: -2.1479507 | AB27: -79.884499 | AC27: 0 | AD27: =+VLOOKUP(L27,Evalua!$G$2:$H$12,2,0) -> 1 | AE27: =+VLOOKUP(M27,Evalua!$G$2:$H$12,2,0) -> 2
A28: 146 | B28: ATM - TIA LOS ESTEROS | E28: 5-10m | G28: MATRIZ-TEVCOL | H28: NO | I28: ABIERTO | J28: ISLA | K28: Gerardo Pulgarín | L28: Bajo / Seguro | M28: Media (Cortes esporádicos) | N28: =+VLOOKUP(A28,[1]Buscador!$B:$E,4,0) -> Guayaquil | O28: =+VLOOKUP(A28,[1]Buscador!$B:$F,5,0) -> Guayas | P28: NO | S28: Bajo / SeguroMedia (Cortes esporádicos) | T28: N3 Moderado | U28: ATM - TIA LOS ESTEROS | V28: NO | W28: ATM - TIA SOLANDA | X28: 146-ATM - TIA LOS ESTEROS | Y28: (92-ATM - TIA SOLANDA) | Z28: -2.2509105545268, -79.899715862022 | AA28: -2.2509106 | AB28: -79.899716 | AC28: 0 | AD28: =+VLOOKUP(L28,Evalua!$G$2:$H$12,2,0) -> 1 | AE28: =+VLOOKUP(M28,Evalua!$G$2:$H$12,2,0) -> 2
A29: 15 | B29: ATM - OF. MERCADO CENTRAL | D29: Medio-Alto | E29: 10-15m | G29: MERCADO CENTRAL | H29: NO | I29: ABIERTO | J29: OFICINA | K29: Gerardo Pulgarín | L29: Bajo / Seguro | M29: Media (Cortes esporádicos) | N29: =+VLOOKUP(A29,[1]Buscador!$B:$E,4,0) -> Guayaquil | O29: =+VLOOKUP(A29,[1]Buscador!$B:$F,5,0) -> Guayas | P29: NO | S29: Bajo / SeguroMedia (Cortes esporádicos) | T29: N3 Moderado | U29: MERCADO CENTRAL | V29: NO | X29: 15-ATM - OF. MERCADO CENTRAL | Z29: -2.1931403563253, -79.888195372799 | AA29: -2.1931404 | AB29: -79.888195 | AC29: 0 | AD29: =+VLOOKUP(L29,Evalua!$G$2:$H$12,2,0) -> 1 | AE29: =+VLOOKUP(M29,Evalua!$G$2:$H$12,2,0) -> 2
A30: 150 | B30: ATM - ACERO COMERCIAL QUITO | G30: MATRIZ-TEVCOL | H30: NO | I30: ABIERTO | J30: ISLA | K30: Fernando Peralta | L30: Medio (Se inunda la calle) | M30: Media (Cortes esporádicos) | N30: =+VLOOKUP(A30,[1]Buscador!$B:$E,4,0) -> Quito | O30: =+VLOOKUP(A30,[1]Buscador!$B:$F,5,0) -> Pichincha | P30: NO | S30: Medio (Se inunda la calle)Media (Cortes esporádicos) | T30: N2 Alto | U30: ATM - ACERO COMERCIAL QUITO | V30: NO | W30: ATM - AVÍCOLA FERNANDEZ BABAHOYO | X30: 150-ATM - ACERO COMERCIAL QUITO | Y30: (496-ATM - AVÍCOLA FERNANDEZ BABAHOYO) | Z30: -0.158622, -78.488167 | AA30: -0.158622 | AB30: -78.488167 | AC30: 0 | AD30: =+VLOOKUP(L30,Evalua!$G$2:$H$12,2,0) -> 3 | AE30: =+VLOOKUP(M30,Evalua!$G$2:$H$12,2,0) -> 2
A31: 151 | B31: ATM - FARM. VICTORIA 29 Y ORIENTE | C31: Suburbio se inunda todo | D31: Alto | E31: 5-10m | G31: MATRIZ-TEVCOL | H31: NO | I31: ABIERTO | J31: ISLA | K31: Gerardo Pulgarín | L31: Medio (Se inunda la calle) | M31: Alta (Corte inmediato) | N31: =+VLOOKUP(A31,[1]Buscador!$B:$E,4,0) -> Guayaquil | O31: =+VLOOKUP(A31,[1]Buscador!$B:$F,5,0) -> Guayas | P31: NO | S31: Medio (Se inunda la calle)Alta (Corte inmediato) | T31: N1 Crítico | U31: ATM - FARM. VICTORIA 29 Y ORIENTE | V31: NO | W31: ATM - GISIS | X31: 151-ATM - FARM. VICTORIA 29 Y ORIENTE | Y31: (464-ATM - GISIS) | Z31: -2.2111070203254, -79.930980380145 | AA31: -2.211107 | AB31: -79.93098 | AC31: 0 | AD31: =+VLOOKUP(L31,Evalua!$G$2:$H$12,2,0) -> 3 | AE31: =+VLOOKUP(M31,Evalua!$G$2:$H$12,2,0) -> 1
A32: 152 | B32: ATM - HOTEL MONTAÑITA | E32: 5-10m | G32: MATRIZ-TEVCOL | H32: SI | I32: ABIERTO | J32: ISLA | K32: Gerardo Pulgarín | L32: Bajo / Seguro | M32: Media (Cortes esporádicos) | N32: =+VLOOKUP(A32,[1]Buscador!$B:$E,4,0) -> Montañita | O32: =+VLOOKUP(A32,[1]Buscador!$B:$F,5,0) -> Santa Elena | P32: Generador | S32: Bajo / SeguroMedia (Cortes esporádicos) | T32: N3 Moderado | U32: ATM - HOTEL MONTAÑITA | V32: OLEAJE | W32: ATM - LOS CEIBOS FF AUTOCAJERO | X32: 152-ATM - HOTEL MONTAÑITA | Y32: (415-ATM - LOS CEIBOS FF AUTOCAJERO) | Z32: -1.8266960736485, -80.753190150188 | AA32: -1.8266961 | AB32: -80.75319 | AC32: 0 | AD32: =+VLOOKUP(L32,Evalua!$G$2:$H$12,2,0) -> 1 | AE32: =+VLOOKUP(M32,Evalua!$G$2:$H$12,2,0) -> 2
A33: 153 | B33: ATM - STA. CRUZ GALAPAGOS | G33: MATRIZ-TEVCOL | H33: NO | I33: ABIERTO | J33: ISLA | K33: José Chiliguana | L33: Crítico (Se inunda punto de atención) | M33: Baja (Línea prioritaria) | N33: =+VLOOKUP(A33,[1]Buscador!$B:$E,4,0) -> Puerto Ayora | O33: =+VLOOKUP(A33,[1]Buscador!$B:$F,5,0) -> Galápagos | P33: NO | S33: Crítico (Se inunda punto de atención)Baja (Línea prioritaria) | T33: N2 Alto | U33: ATM - STA. CRUZ GALAPAGOS | V33: NO | W33: ATM - TIA COTOCOLLAO | X33: 153-ATM - STA. CRUZ GALAPAGOS | Y33: (460-ATM - TIA COTOCOLLAO) | Z33: -0.74773832152368, -90.313735658583 | AA33: -0.74773832 | AB33: -90.313736 | AC33: 0 | AD33: =+VLOOKUP(L33,Evalua!$G$2:$H$12,2,0) -> 4 | AE33: =+VLOOKUP(M33,Evalua!$G$2:$H$12,2,0) -> 3
A34: 154 | B34: ATM - OF. LA CONCORDIA | G34: LA CONCORDIA | H34: NO | I34: ABIERTO | J34: OFICINA | K34: Carlos Morán | L34: Bajo / Seguro | M34: Baja (Línea prioritaria) | N34: =+VLOOKUP(A34,[1]Buscador!$B:$E,4,0) -> San Isidro | O34: =+VLOOKUP(A34,[1]Buscador!$B:$F,5,0) -> Santo Domingo de los Tsáchilas | P34: Generador | S34: Bajo / SeguroBaja (Línea prioritaria) | T34: N4 Bajo | U34: LA CONCORDIA | V34: NO | W34: RÍO PLAZA | X34: 154-ATM - OF. LA CONCORDIA | Y34: (23-ATM - C.C. RIO PLAZA OF.) + (A0102-RÍO PLAZA) | Z34: 0.0047511679635608, -79.397524259818 | AA34: 0.004751168 | AB34: -79.397524 | AC34: 0 | AD34: =+VLOOKUP(L34,Evalua!$G$2:$H$12,2,0) -> 1 | AE34: =+VLOOKUP(M34,Evalua!$G$2:$H$12,2,0) -> 3
A35: 158 | B35: ATM - TIA PASCUALES | E35: 5-10m | G35: MATRIZ-TEVCOL | H35: NO | I35: ABIERTO | J35: ISLA | K35: Gerardo Pulgarín | L35: Medio (Se inunda la calle) | M35: Media (Cortes esporádicos) | N35: =+VLOOKUP(A35,[1]Buscador!$B:$E,4,0) -> Guayaquil | O35: =+VLOOKUP(A35,[1]Buscador!$B:$F,5,0) -> Guayas | P35: Generador | S35: Medio (Se inunda la calle)Media (Cortes esporádicos) | T35: N2 Alto | U35: ATM - TIA PASCUALES | V35: NO | W35: ATM - TUTI DURANEL RECREO 1° ETAPA | X35: 158-ATM - TIA PASCUALES | Y35: (543-ATM - TUTI DURANEL RECREO 1° ETAPA) | Z35: -2.0684263198515, -79.933219747781 | AA35: -2.0684263 | AB35: -79.93322 | AC35: 0 | AD35: =+VLOOKUP(L35,Evalua!$G$2:$H$12,2,0) -> 3 | AE35: =+VLOOKUP(M35,Evalua!$G$2:$H$12,2,0) -> 2
A36: 159 | B36: ATM - GAS. PETROLEOS Y SERVICIOS | E36: 0-5m | G36: MATRIZ-TEVCOL | H36: SI | I36: ABIERTO | J36: ISLA | K36: Gerardo Pulgarín | L36: Bajo / Seguro | M36: Media (Cortes esporádicos) | N36: =+VLOOKUP(A36,[1]Buscador!$B:$E,4,0) -> San Pablo | O36: =+VLOOKUP(A36,[1]Buscador!$B:$F,5,0) -> Santa Elena | P36: NO | S36: Bajo / SeguroMedia (Cortes esporádicos) | T36: N3 Moderado | U36: ATM - GAS. PETROLEOS Y SERVICIOS | V36: OLEAJE | W36: ATM - HIPERMARKET MONTECRISTI | X36: 159-ATM - GAS. PETROLEOS Y SERVICIOS | Y36: (454-ATM - HIPERMARKET MONTECRISTI) | Z36: -2.140413, -80.777271 | AA36: -2.140413 | AB36: -80.777271 | AC36: 0 | AD36: =+VLOOKUP(L36,Evalua!$G$2:$H$12,2,0) -> 1 | AE36: =+VLOOKUP(M36,Evalua!$G$2:$H$12,2,0) -> 2
A37: 16 | B37: ATM - C.C. CALIFORNIA 1 OF. | D37: Alto | E37: 10-20m | G37: PARQUE INDUSTRIAL CALIFORNIA | H37: NO | I37: ABIERTO | J37: OFICINA | K37: Gerardo Pulgarín | L37: Medio (Se inunda la calle) | M37: Baja (Línea prioritaria) | N37: =+VLOOKUP(A37,[1]Buscador!$B:$E,4,0) -> Guayaquil | O37: =+VLOOKUP(A37,[1]Buscador!$B:$F,5,0) -> Guayas | P37: Generador | S37: Medio (Se inunda la calle)Baja (Línea prioritaria) | T37: N3 Moderado | U37: PARQUE INDUSTRIAL CALIFORNIA | V37: NO | X37: 16-ATM - C.C. CALIFORNIA 1 OF. | Z37: -2.098622, -79.936398 | AA37: -2.098622 | AB37: -79.936398 | AC37: 0 | AD37: =+VLOOKUP(L37,Evalua!$G$2:$H$12,2,0) -> 3 | AE37: =+VLOOKUP(M37,Evalua!$G$2:$H$12,2,0) -> 3
A38: 160 | B38: ATM - NATURISSIMO | D38: Bajo | E38: 10-15m | G38: MATRIZ-TEVCOL | H38: NO | I38: ABIERTO | J38: ISLA | K38: Gerardo Pulgarín | L38: Bajo / Seguro | M38: Media (Cortes esporádicos) | N38: =+VLOOKUP(A38,[1]Buscador!$B:$E,4,0) -> Salinas | O38: =+VLOOKUP(A38,[1]Buscador!$B:$F,5,0) -> Santa Elena | P38: NO | S38: Bajo / SeguroMedia (Cortes esporádicos) | T38: N3 Moderado | U38: ATM - NATURISSIMO | V38: OLEAJE | W38: ATM - PLAZA LAGOS - MULTI | X38: 160-ATM - NATURISSIMO | Y38: (278-ATM - PLAZA LAGOS - MULTI) | Z38: -2.2052601382149, -80.95853400435 | AA38: -2.2052601 | AB38: -80.958534 | AC38: 0 | AD38: =+VLOOKUP(L38,Evalua!$G$2:$H$12,2,0) -> 1 | AE38: =+VLOOKUP(M38,Evalua!$G$2:$H$12,2,0) -> 2
A39: 164 | B39: ATM - SANGOLQUI 2 | G39: MATRIZ-TEVCOL | H39: NO | I39: ABIERTO | J39: ISLA | K39: Fernando Peralta | L39: Bajo / Seguro | M39: Media (Cortes esporádicos) | N39: =+VLOOKUP(A39,[1]Buscador!$B:$E,4,0) -> Sangolquí | O39: =+VLOOKUP(A39,[1]Buscador!$B:$F,5,0) -> Pichincha | P39: NO | S39: Bajo / SeguroMedia (Cortes esporádicos) | T39: N3 Moderado | U39: ATM - SANGOLQUI 2 | V39: NO | W39: ATM - TIA ALBORADA | X39: 164-ATM - SANGOLQUI 2 | Y39: (141-ATM - TIA ALBORADA) | Z39: -0.32772240690324, -78.450253377416 | AA39: -0.32772241 | AB39: -78.450253 | AC39: 0 | AD39: =+VLOOKUP(L39,Evalua!$G$2:$H$12,2,0) -> 1 | AE39: =+VLOOKUP(M39,Evalua!$G$2:$H$12,2,0) -> 2
A40: 165 | B40: ATM - OF. ALBORADA NORTE 1 | D40: Medio-Alto | E40: 5-10m | G40: ALBORADA NORTE | H40: NO | I40: ABIERTO | J40: OFICINA | K40: Gerardo Pulgarín | L40: Medio (Se inunda la calle) | M40: Media (Cortes esporádicos) | N40: =+VLOOKUP(A40,[1]Buscador!$B:$E,4,0) -> Guayaquil | O40: =+VLOOKUP(A40,[1]Buscador!$B:$F,5,0) -> Guayas | P40: Generador | S40: Medio (Se inunda la calle)Media (Cortes esporádicos) | T40: N2 Alto | U40: ALBORADA NORTE | V40: NO | W40: ARCA CALDERON | X40: 165-ATM - OF. ALBORADA NORTE 1 | Y40: (A0092-ARCA CALDERON) | Z40: -2.1335977860225, -79.904058839287 | AA40: -2.1335978 | AB40: -79.904059 | AC40: 0 | AD40: =+VLOOKUP(L40,Evalua!$G$2:$H$12,2,0) -> 3 | AE40: =+VLOOKUP(M40,Evalua!$G$2:$H$12,2,0) -> 2
...

Sheet Evalua
A1: ID | B1: Inundación | C1: Energía | D1: Nivel
A2: Crítico (Se inunda punto de atención)Alta (Corte inmediato) | B2: Crítico (Se inunda punto de atención) | C2: Alta (Corte inmediato) | D2: N1 Crítico | G2: {=+_xlfn.UNIQUE(Hoja1!L:L)} -> NIVEL DE RIESGO INUNDACION
A3: Crítico (Se inunda punto de atención)Media (Cortes esporádicos) | B3: Crítico (Se inunda punto de atención) | C3: Media (Cortes esporádicos) | D3: N1 Crítico | G3: Bajo / Seguro | H3: 1
A4: Crítico (Se inunda punto de atención)Baja (Línea prioritaria) | B4: Crítico (Se inunda punto de atención) | C4: Baja (Línea prioritaria) | D4: N2 Alto | G4: Medio (Se inunda la calle) | H4: 3
A5: Medio (Se inunda la calle)Alta (Corte inmediato) | B5: Medio (Se inunda la calle) | C5: Alta (Corte inmediato) | D5: N1 Crítico | G5: Crítico (Se inunda punto de atención) | H5: 4
A6: Medio (Se inunda la calle)Media (Cortes esporádicos) | B6: Medio (Se inunda la calle) | C6: Media (Cortes esporádicos) | D6: N2 Alto | G6: Medio (Filtracion superficial) | H6: 2
A7: Medio (Se inunda la calle)Baja (Línea prioritaria) | B7: Medio (Se inunda la calle) | C7: Baja (Línea prioritaria) | D7: N3 Moderado | G7: 0
A8: Bajo / SeguroAlta (Corte inmediato) | B8: Bajo / Seguro | C8: Alta (Corte inmediato) | D8: N2 Alto
A9: Bajo / SeguroMedia (Cortes esporádicos) | B9: Bajo / Seguro | C9: Media (Cortes esporádicos) | D9: N3 Moderado | G9: {=+_xlfn.UNIQUE(Hoja1!M:M)} -> SENSIBILIDAD A CORTES ELECTRICOS
A10: Bajo / SeguroBaja (Línea prioritaria) | B10: Bajo / Seguro | C10: Baja (Línea prioritaria) | D10: N4 Bajo | G10: Media (Cortes esporádicos) | H10: 2
A11: Medio (Filtracion superficial)Alta (Corte inmediato) | B11: Medio (Filtracion superficial) | C11: Alta (Corte inmediato) | D11: N2 Alto | G11: Baja (Línea prioritaria) | H11: 3
A12: Medio (Filtracion superficial)Media (Cortes esporádicos) | B12: Medio (Filtracion superficial) | C12: Media (Cortes esporádicos) | D12: N3 Moderado | G12: Alta (Corte inmediato) | H12: 1
A13: Medio (Filtracion superficial)Baja (Línea prioritaria) | B13: Medio (Filtracion superficial) | C13: Baja (Línea prioritaria) | D13: N4 Bajo | G13: 0

Sheet Hoja2
A1: ¿Nivel de Riesgo Inundación? | C1: ¿Sensibilidad a Cortes Eléctricos?
A2: Crítico (Se inunda punto de atención) | B2: Requiere obras físicas / mover equipos. | C2: Alta (Corte inmediato) | D2: Alta (Corte inmediato) | E2: Alta (Corte inmediato) | F2: Se va la luz apenas llueve o parpadea la red.
A3: Medio (Se inunda la calle) | B3: Afecta acceso de clientes y técnicos. | C3: Media (Cortes esporádicos) | D3: Media (Cortes esporádicos) | E3: Media (Cortes esporádicos) | F3: La red de la zona es relativamente estable.
A4: Bajo / Seguro | B4: Zona segura contra lluvias. | C4: Baja (Línea prioritaria) | D4: Baja (Línea prioritaria) | E4: Baja (Línea prioritaria) | F4: Zona de hospitales, centros cívicos o industrias.
A5: Medio (Filtracion superficial)

Sheet Hoja3
A1: ID | B1: Nombre | C1: Punto de atencion | D1: Ciudad | E1: Inundacion | F1: Electricidad | G1: Nivel | P1: Provincia | Q1: Puntos | R1: N1 | S1: N2 | T1: N3 | U1: N4
A2: 48 | B2: AMBATO CENTRO | C2: (48-ATM - OF. AMBATO CENTRO) + (A0074-AMBATO) | D2: AMBATO | E2: Crítico (Se inunda punto de atención) | F2: Media (Cortes esporádicos) | G2: N1 Crítico | P2: Guayas | Q2: 185 | R2: 7 | S2: 13 | T2: 165 | U2: 0
A3: 63 | B3: MILAGRO | C3: (63-ATM - OF. MILAGRO) + (360-ATM - OF. MILAGRO 2) + (A0022-MILAGRO) | D3: MILAGRO | E3: Crítico (Se inunda punto de atención) | F3: Media (Cortes esporádicos) | G3: N1 Crítico | P3: Pichincha | Q3: 45 | R3: 2 | S3: 4 | T3: 39 | U3: 0
A4: 77 | B4: BABAHOYO | C4: (77-ATM - OF. BABAHOYO) + (A0004-BABAHOYO) | D4: BABAHOYO | E4: Medio (Se inunda la calle) | F4: Alta (Corte inmediato) | G4: N1 Crítico | P4: Manabí | Q4: 14 | R4: 5 | S4: 7 | T4: 1 | U4: 1
A5: 125 | B5: ATM - FARM. PHARMACYS BATAN BAJO | C5: (125-ATM - FARM. PHARMACYS BATAN BAJO) | D5: QUITO | E5: Medio (Se inunda la calle) | F5: Alta (Corte inmediato) | G5: N1 Crítico | P5: Santa Elena | Q5: 13 | R5: 0 | S5: 0 | T5: 13 | U5: 0
A6: 151 | B6: ATM - FARM. VICTORIA 29 Y ORIENTE | C6: (151-ATM - FARM. VICTORIA 29 Y ORIENTE) | D6: GUAYAQUIL | E6: Medio (Se inunda la calle) | F6: Alta (Corte inmediato) | G6: N1 Crítico | P6: Los Ríos | Q6: 8 | R6: 3 | S6: 5 | T6: 0 | U6: 0
A7: 216 | B7: ATM - MAPASINGUE OESTE | C7: (216-ATM - MAPASINGUE OESTE) | D7: GUAYAQUIL | E7: Medio (Se inunda la calle) | F7: Alta (Corte inmediato) | G7: N1 Crítico | P7: Azuay | Q7: 7 | R7: 0 | S7: 2 | T7: 5 | U7: 0
A8: 221 | B8: ATM - SAUCES VI | C8: (221-ATM - SAUCES VI) | D8: GUAYAQUIL | E8: Crítico (Se inunda punto de atención) | F8: Media (Cortes esporádicos) | G8: N1 Crítico | P8: Tungurahua | Q8: 6 | R8: 1 | S8: 2 | T8: 3 | U8: 0
A9: 301 | B9: ATM - MANTA FLAVIO REYES Y CALLE | C9: (301-ATM - MANTA FLAVIO REYES Y CALLE) | D9: MANTA | E9: Crítico (Se inunda punto de atención) | F9: Alta (Corte inmediato) | G9: N1 Crítico | P9: Sto Domingo | Q9: 5 | R9: 0 | S9: 2 | T9: 0 | U9: 3
A10: 332 | B10: ATM - TIA DURAN III | C10: (332-ATM - TIA DURAN III) | D10: DURAN | E10: Medio (Se inunda la calle) | F10: Alta (Corte inmediato) | G10: N1 Crítico | P10: El Oro | Q10: 3 | R10: 1 | S10: 0 | T10: 0 | U10: 2
A11: 336 | B11: ATM - TER. TERREST. PORTOVIEJO | C11: (336-ATM - TER. TERREST. PORTOVIEJO) | D11: PORTOVIEJO | E11: Medio (Se inunda la calle) | F11: Alta (Corte inmediato) | G11: N1 Crítico | P11: Cañar | Q11: 3 | R11: 0 | S11: 0 | T11: 3 | U11: 0
A12: 392 | B12: ATM - PASEO SHOPPING BABAHOYO | C12: (392-ATM - PASEO SHOPPING BABAHOYO) | D12: BABAHOYO | E12: Crítico (Se inunda punto de atención) | F12: Media (Cortes esporádicos) | G12: N1 Crítico | P12: Loja | Q12: 1 | R12: 0 | S12: 0 | T12: 1 | U12: 0
... A15: 435 | B15: ATM - CENTRO PORTOVIEJO | C15: (435-ATM - CENTRO PORTOVIEJO) | D15: PORTOVIEJO | E15: Crítico (Se inunda punto de atención) | F15: Alta (Corte inmediato) | G15: N1 Crítico | P15: Imbabura | Q15: 1 | R15: 0 | S15: 0 | T15: 1 | U15: 0
A16: 451 | B16: ATM - FARM. CRUZ AZUL POMASQUI | C16: (451-ATM - FARM. CRUZ AZUL POMASQUI) | D16: QUITO | E16: Medio (Se inunda la calle) | F16: Alta (Corte inmediato) | G16: N1 Crítico
A17: 496 | B17: ATM - AVÍCOLA FERNANDEZ BABAHOYO | C17: (496-ATM - AVÍCOLA FERNANDEZ BABAHOYO) | D17: BABAHOYO | E17: Medio (Se inunda la calle) | F17: Alta (Corte inmediato) | G17: N1 Crítico
A18: 543 | B18: ATM - TUTI DURANEL RECREO 1° ETAPA | C18: (543-ATM - TUTI DURANEL RECREO 1° ETAPA) | D18: DURAN | E18: Medio (Se inunda la calle) | F18: Alta (Corte inmediato) | G18: N1 Crítico
A19: 546 | B19: ATM - DURAN EL RECREO 3 ETAPA | C19: (546-ATM - DURAN EL RECREO 3 ETAPA) | D19: DURAN | E19: Medio (Se inunda la calle) | F19: Alta (Corte inmediato) | G19: N1 Crítico
A20: A0036 | B20: ARCA VIA PASAJE MACHALA | C20: (A0036-ARCA VIA PASAJE MACHALA) | D20: MACHALA | E20: Medio (Se inunda la calle) | F20: Alta (Corte inmediato) | G20: N1 Crítico
A21: 2 | B21: URDESA | C21: (2-ATM - OF. URDESA 1) + (52-ATM - OF. URDESA 2) + (A0033-URDESA) | D21: GUAYAQUIL | E21: Medio (Se inunda la calle) | F21: Media (Cortes esporádicos) | G21: N2 Alto
A22: 6 | B22: QUEVEDO | C22: (6-ATM - OF. QUEVEDO) + (373-ATM - OF. QUEVEDO 2) + (A0028-QUEVEDO) | D22: QUEVEDO | E22: Bajo / Seguro | F22: Alta (Corte inmediato) | G22: N2 Alto
A23: 21 | B23: VIA DAULE | C23: (21-ATM - GAS. MOBIL VIA DAULE OF.) + (A0069-VIA DAULE) | D23: GUAYAQUIL | E23: Medio (Se inunda la calle) | F23: Media (Cortes esporádicos) | G23: N2 Alto
A24: 28 | B24: MANTA | C24: (28-ATM - OF. MANTA) + (A0019-MANTA) | D24: MANTA | E24: Medio (Se inunda la calle) | F24: Media (Cortes esporádicos) | G24: N2 Alto
A25: 34 | B25: PORTOVIEJO | C25: (34-ATM - OF. PORTOVIEJO) + (A0027-PORTOVIEJO) | D25: PORTOVIEJO | E25: Medio (Se inunda la calle) | F25: Media (Cortes esporádicos) | G25: N2 Alto
A26: 40 | B26: EL EMPALME | C26: (40-ATM - OF. EL EMPALME) + (356-ATM - OF EL EMPALME 2) + (A0009-EL EMPALME) | D26: EL EMPALME | E26: Bajo / Seguro | F26: Alta (Corte inmediato) | G26: N2 Alto
A27: 42 | B27: BUENA FE | C27: (42-ATM - OF. BUENA FE) + (A0005-BUENA FE) | D27: BUENA FE | E27: Bajo / Seguro | F27: Alta (Corte inmediato) | G27: N2 Alto
... A295: 447 | B295: MACHALA | C295: (447-ATM - AG. MACHALA) + (A0016-MACHALA) | D295: MACHALA | E295: Bajo / Seguro | F295: Baja (Línea prioritaria) | G295: N4 Bajo
